Workbook
Name PartsMaster: Parts[#All]

Sheet PartsMaster
A1: Jaguar PN (S) | B1: Model | C1: Part | D1: Stock | E1: Jaguar ProdName | F1: VINmin | G1: VINmax | H1: Part type | I1: Functionality | J1: Int / Ext / Engine Bay / Trunk | K1: Loc | L1: LocSide | M1: LocVertical | N1: LocPos | O1: Colour/Trim | P1: Superseded PNs | Q1: Vendor Part Name | R1: Vendor PN | S1: Price EU euro | T1: eBay Listed | U1: Price Euro | V1: Price PoundS | W1: PackSize XS/S/M/L/XL/C | X1: Shipping Inc/Exl | Y1: URL | Z1: Referrence Document | AA1: Special Notes | AB1: Vendor / Donor Car | AC1: Donor Mileage Kilometers | AD1: Vendors | AE1: Stock value
A2: ACC1269KIT | B2: Jaguar XK8 XKR X100 | C2: Timing Chain Service Kit (no Crank Bold) | D2: 0 | H2: Kit | I2: Engine Timing | Q2: TIMING GEAR SERVICE KIT | R2: ACC1269KIT | T2: 0 | AB2: British Parts | AC2: =68000*1.61 -> 109480 | AE2: =S2*D2 -> 0
A3: AGU2436J | B3: Jaguar XK8 XKR X100 | C3: Wheelarch Liner - Plastic push on nut | H3: Bolt / Screw | I3: Mounting | J3: Exterior | K3: Front/Rear | L3: Left/Right | Q3: NUT-PLASTIC | R3: =A3 -> AGU2436J | T3: 0 | U3: £0.47 | AB3: SNG Barratt | AC3: =68000*1.61 -> 109480 | AE3: =S3*D3 -> 0
A4: AGU2530 | B4: Jaguar XK8 XKR X100 | C4: Trunk lining mount rivets | D4: 6 | E4: Trunc Lid Liner Push in fastener | H4: Interior trim | I4: Fastener / Fir-tree / Rivet | K4: Rear | M4: Top | Q4: FASTENER-PUS | R4: =A4 -> AGU2530 | S4: 1 | T4: 0 | U4: =Parts[[#This Row],[Price EU euro]] -> 1 | V4: =Parts[[#This Row],[Price Euro]]/1.16 -> 0.86206897 | X4: 2 | AB4: Dismantled from bottom & engine damaged MY1997 XK8 Convertible VIN 0136xx | AC4: =68000*1.61 -> 109480 | AE4: =S4*D4 -> 6
A5: AJ82217KIT1A | B5: Jaguar XK8 XKR X100 | C5: =Q5 -> THERMOSTAT KIT-ALUMINIUM | D5: 0 | H5: Kit | I5: Engine Cooling | Q5: THERMOSTAT KIT-ALUMINIUM | R5: =A5 -> AJ82217KIT1A | T5: 0 | AB5: British Parts | AC5: =68000*1.61 -> 109480 | AE5: =S5*D5 -> 0
A6: AJ82325 | B6: Jaguar XK8 XKR X100 | C6: Timing Chain Tensioner Primary | D6: 1 | F6: X100, 1996 - X308, 1997 | G6: X100, 2006 - X308, 2002 | H6: Chain tensioner | I6: Engine Timing | Q6: TIMING CHAIN TENSIONER | R6: =A6 -> AJ82325 | T6: 0 | AB6: British Parts | AC6: =68000*1.61 -> 109480 | AE6: =S6*D6 -> 0
A7: AJ82856 | B7: Jaguar XK8 XKR X100 | C7: =Q7 -> CAMSHAFT COVER SEAL-VVT | H7: Gasket / Seal / O-Ring | I7: Engine Oil | Q7: CAMSHAFT COVER SEAL-VVT | R7: =A7 -> AJ82856 | T7: 0 | AB7: British Parts | AC7: =68000*1.61 -> 109480 | AE7: =S7*D7 -> 0
A8: AJ82856 | B8: Jaguar XK8 XKR X100 XJ8 XJR X308 | C8: Seal Camshaft Cover VVT | F8: X100, 1996 - X308, 1997 | G8: X100, 2006 - X308, 2002 | H8: Seal / Insulation | R8: AJ82856 | T8: 0 | AC8: =68000*1.61 -> 109480 | AE8: =S8*D8 -> 0
A9: AJ83698 | B9: Jaguar XK8 XKR X100 | C9: =Q9 -> OIL SEAL-CRANKSHAFT | H9: Gasket / Seal / O-Ring | I9: Engine Oil | Q9: OIL SEAL-CRANKSHAFT | R9: =A9 -> AJ83698 | T9: 0 | AB9: British Parts | AC9: =68000*1.61 -> 109480 | AE9: =S9*D9 -> 0
A10: AJ83699 | B10: Jaguar XK8 XKR X100 XJ8 XJR X308 | C10: Timing Cover Seal Inner | F10: X100, 1996 - X308, 1997 | G10: X100, 2006 - X308, 2002 | H10: Gasket / Seal / O-Ring | I10: Engine timing | Q10: Timing Cover Seal Inner | R10: AJ83699 | T10: 0 | AC10: =68000*1.61 -> 109480 | AE10: =S10*D10 -> 0
A11: AJ83744 | B11: Jaguar XK8 XKR X100 | C11: Crankshaft Oil Seal | H11: Gasket / Seal / O-Ring | I11: Engine Oil | Q11: OIL SEAL-CRANKSHAFT | R11: =A11 -> AJ83744 | T11: 0 | AB11: British Parts | AC11: =68000*1.61 -> 109480 | AE11: =S11*D11 -> 0
A12: AJ86484 | B12: Jaguar XK8 XKR X100 | C12: =Q12 -> THERMOSTAT | D12: 0 | H12: Switch | I12: Engine Cooling | Q12: THERMOSTAT | R12: =A12 -> AJ86484 | T12: 0 | AB12: British Parts | AC12: =68000*1.61 -> 109480 | AE12: =S12*D12 -> 0
A13: AJ87242 | B13: Jaguar XK8 XKR X100 | C13: =Q13 -> CAMSHAFT COVER CENTRE SEAL | H13: Gasket / Seal / O-Ring | I13: Engine Oil | Q13: CAMSHAFT COVER CENTRE SEAL | R13: =A13 -> AJ87242 | T13: 0 | AB13: British Parts | AC13: =68000*1.61 -> 109480 | AE13: =S13*D13 -> 0
A14: AJ88285 | B14: Jaguar XK8 XKR X100 XJ8 XJR X308 | C14: Gasket Camshaft Cover B-Bank | F14: Engine #9810290000 | H14: Gasket / Seal / O-Ring | J14: Engine Bay | L14: Left | Q14: Cam Cover Gasket LH B Bank | R14: AJ88285 | S14: 21 | T14: 0 | AC14: =68000*1.61 -> 109480 | AE14: =S14*D14 -> 0
A15: AJ88400 | B15: Jaguar XK8 XKR X100 XJ8 XJR X308 | C15: Gasket Camshaft Cover A-Bank | F15: Engine #9810290000 | H15: Gasket / Seal / O-Ring | J15: Engine Bay | L15: Right | Q15: Cam Cover Gasket RH A Bank | R15: AJ88400 | S15: 21 | T15: 0 | AC15: =68000*1.61 -> 109480 | AE15: =S15*D15 -> 0
A16: AJ88912G | B16: Jaguar XK8 XKR X100 | C16: WATER PUMP OE | D16: 0 | H16: Pump | I16: Engine Cooling | Q16: WATER PUMP-JAGUAR | R16: AJ88912G | T16: 0 | AB16: British Parts | AC16: =68000*1.61 -> 109480 | AE16: =S16*D16 -> 0
A17: AJ88922 | B17: Jaguar XK8 XKR X100 | C17: =Q17 -> WATER PUMP GASKET | H17: Gasket / Seal / O-Ring | I17: Engine Cooling | Q17: WATER PUMP GASKET | R17: =A17 -> AJ88922 | T17: 0 | AB17: British Parts | AC17: =68000*1.61 -> 109480 | AE17: =S17*D17 -> 0
A18: AJ89909 | B18: Jaguar XK8 XKR X100 XJ8 XJR X308 | C18: Crankshaft Damper Bolt | D18: 0 | E18: Jaguar Crankshaft Front Damper Bolt | F18: XK8 4.0 V8 1996 X308 XJ8 3.2 & 4.0 V8 1998 S Type 4.0 V8 XJ X350 2003 | G18: XK8 4.0 V8 2006 X308 XJ8 3.2 & 4.0 V8 2002 S Type 4.0 V8 N52047 XJ X350 Vin G49700 | H18: Bolt / Screw | I18: Engine | J18: Engine bay | K18: Front | Q18: Crankshaft Bolt | R18: AJ89909 | T18: 0 | U18: £7.36 | AB18: British Parts | AC18: =68000*1.61 -> 109480 | AE18: =S18*D18 -> 0
A19: AJ89986 | B19: Jaguar XK8 XKR X100 | C19: =Q19 -> CYLINDER HEAD BOLT | H19: Bolt / Screw | I19: Engine | Q19: CYLINDER HEAD BOLT | R19: =A19 -> AJ89986 | T19: 0 | AB19: British Parts | AC19: =68000*1.61 -> 109480 | AE19: =S19*D19 -> 0
A20: Balljoint-Boot | B20: Jaguar XK8 XKR X100 XJ8 XJR X308 | C20: Ball joint boot | D20: 4 | E20: N/A | F20: X100 MY1996 - X308 MY1998 | G20: X100 MY2006 - X308 All | H20: Boot | I20: Suspension | J20: Exterior | K20: Front | L20: Left/Right | M20: Top(?) | S20: 2 | U20: =Parts[[#This Row],[Stock]]*Parts[[#This Row],[Price EU euro]] -> 8 | W20: S | Z20: https://www.motonet.fi/fi/kategoria/887/1002746/Alustan-yleisvaraosat | AA20: Not known if these are for upper or lower ball joints. | AE20: =S20*D20 -> 8
A21: BCC9610 JZS100041 | B21: Jaguar XK8 XKR X100 | C21: Seat - Mount Torx | H21: Bolt / Screw | I21: Mounting | K21: Front | L21: Left/Right | M21: Low | Q21: SCREW-TORX | R21: JZS100041 | T21: 0 | U21: £0.46 | AB21: SNG Barrat | AC21: =68000*1.61 -> 109480 | AE21: =S21*D21 -> 0
A22: C21069 | B22: Jaguar XK8 XKR X100 | C22: Seat - Mount Washer | H22: Washer | I22: Mounting | K22: Front | L22: Left/Right | M22: Low | Q22: WASHER | R22: =A22 -> C21069 | T22: 0 | U22: £1.01 | AB22: SNG Barrat | AC22: =68000*1.61 -> 109480 | AE22: =S22*D22 -> 0
A23: C2A1497 | B23: Jaguar XK8 XKR X100 XJ8 XJR X308 | C23: Timing Chain Tensioner Blade | F23: X100, 1996 - X308, 1998 | G23: X100-X308 Engine #0108122359 | H23: Chain guide / Blade | I23: Engine Timing | Q23: Timing Chain Tensioner Blade | R23: =A23 -> C2A1497 | T23: 0 | AB23: British Parts | AC23: =68000*1.61 -> 109480 | AE23: =S23*D23 -> 0
A24: C2A1511 | B24: Jaguar XK8 XKR X100 XJ8 XJR X308 | C24: Timing Chain Tensioner Secondary RH A Bank | F24: X100, 1996 - X308, 1997 | G24: X100, 2006 - X308, 2002 | H24: Chain tensioner | I24: Engine Timing | Q24: TIMING CHAIN TENSIONER | R24: =A24 -> C2A1511 | T24: 0 | AB24: British Parts | AC24: =68000*1.61 -> 109480 | AE24: =S24*D24 -> 0
A25: C2A1512 | B25: Jaguar XK8 XKR X100 XJ8 XJR X308 | C25: Timing Chain Tensioner Secondary LH B Bank | F25: X100, 1996 - X308, 1997 | G25: X100, 2006 - X308, 2002 | H25: Chain tensioner | I25: Engine Timing | Q25: TIMING CHAIN TENSIONER | R25: =A25 -> C2A1512 | T25: 0 | AB25: British Parts | AC25: =68000*1.61 -> 109480 | AE25: =S25*D25 -> 0
A26: C2C1127 | B26: Jaguar S-Type X200 | C26: Starter Motor | D26: 1 | E26: S-TYPE/BATTERY/STARTER MOTOR/ALTERNATOR/STARTER MOTOR | G26: M45254 | H26: Motor | I26: Start | J26: Engine bay | K26: Front | L26: NA | M26: NA | N26: NA | O26: NA | Q26: Starter Motor | R26: XW4U-11000-AC | S26: 65 | T26: 1 | U26: 65 | X26: included | AB26: Extra working spare | AC26: =68000*1.61 -> 109480 | AD26: SJ | AE26: =S26*D26 -> 65
A27: C2C22758 | B27: Jaguar XK8 XKR X100 | C27: Engine Drive Belt Idler Pulley (kia?) | D27: 0 | F27: XK8 4.0 V8 1996 X308 XJ8 & XJR V8 1997 S Type V8 2002 M45255 | G27: XK8 2006 X308 XJ8 & XJR V8 2002 S Type V8 2009 | I27: Engine | Q27: Idler Pulley | R27: =A27 -> C2C22758 | T27: 0 | U27: £29.99 | AC27: =68000*1.61 -> 109480 | AE27: =S27*D27 -> 0
A28: C2C6884 | B28: Jaguar XJ8 XJR X308 | C28: Cabin Fresh Air Pollen Filter | H28: Filter | S28: 20 | T28: 0 | AC28: =68000*1.61 -> 109480 | AE28: =S28*D28 -> 0
A29: C2S9354020 / KRS113230 | B29: Jaguar XK8 XKR X100 | C29: Wheelarch Liner - Plastic Screw rivet | H29: Bolt / Screw | I29: Mounting | J29: Exterior | K29: Front | L29: Left/Right | Q29: RIVET | R29: C2S9354020 | T29: 0 | U29: £0.26 | AB29: SNG Barratt | AC29: =68000*1.61 -> 109480 | AE29: =S29*D29 -> 0
A30: CAC4610 | B30: Jaguar XK8 XKR X100 XJ6 X300 XJ8 X308 | C30: Bearing Hub Pivot | D30: 2 | E30: STEERING AND SUSPENSION/HUB AND CARRIER-REAR - Taper roller bearing | H30: Bearing | I30: Bearing | K30: Rear | L30: Left/right | M30: Bottom | N30: N/A | Q30: Hub Pivot Bearing | R30: =A30 -> CAC4610 | S30: 15 | T30: 0 | U30: =S30 -> 15 | X30: excluded | AB30: new extra spare | AC30: =68000*1.61 -> 109480 | AD30: JP | AE30: =S30*D30 -> 30
A31: CAC6332 | B31: Jaguar XK8 XKR X100 | C31: Wheel Bearing - Inner | D31: 0 | E31: STEERING AND SUSPENSION/HUB AND CARRIER-REAR - Hub bearing inner | F31: 0 | G31: 031302 | H31: Bearing | I31: Bearing | K31: Rear | L31: Left/Right | R31: =A31 -> CAC6332 | T31: 0 | AC31: =68000*1.61 -> 109480 | AE31: =S31*D31 -> 0
A32: CAC6333 | B32: Jaguar XK8 XKR X100 | C32: Wheel Bearing - Outer | E32: STEERING AND SUSPENSION/HUB AND CARRIER-REAR - Hub bearing outer rear | H32: Bearing | I32: Bearing | K32: Rear | L32: Left/Right | R32: =A32 -> CAC6333 | T32: 0 | AC32: =68000*1.61 -> 109480 | AE32: =S32*D32 -> 0
A33: CAC89682 | B33: Jaguar XK8 XKR X100 | C33: =Q33 -> FUEL FILTER O-RING | H33: Gasket / Seal / O-Ring | I33: Fuel System | Q33: FUEL FILTER O-RING | R33: =A33 -> CAC89682 | T33: 0 | AB33: British Parts | AC33: =68000*1.61 -> 109480 | AE33: =S33*D33 -> 0
A34: CBC1706 | B34: Jaguar XK8 XKR X100 | C34: Wheel Bearing Seal - Inner | E34: STEERING AND SUSPENSION/HUB AND CARRIER-REAR - Inner Seal | H34: Seal / Insulation | I34: Bearing | K34: Rear | L34: Left/Right | R34: =A34 -> CBC1706 | T34: 0 | AC34: =68000*1.61 -> 109480 | AE34: =S34*D34 -> 0
A35: CBC2268 | B35: Jaguar XK8 XKR X100 | C35: Halfshaft | D35: 1 | E35: TRANSMISSION AND DRIVELINE/HALFSHAFTS - Halfshaft | H35: Suspention/rear | I35: Shaft | K35: Rear | L35: Left/Right | M35: Bottom | O35: Black | Q35: Halfshaft | R35: =A35 -> CBC2268 | S35: 95 | T35: 0 | X35: included | AB35: Dismantled from bottom & engine damaged MY1997 XK8 Convertible VIN 0136xx | AC35: =68000*1.61 -> 109480 | AD35: KK | AE35: =S35*D35 -> 95
A36: CBC2964 | B36: Jaguar XK8 XKR X100 | C36: Rear upper link | D36: 1 | E36: STEERING AND SUSPENTION/SUBFRAME AND MOUNTINGS-REAR - Link | H36: Suspention/rear | I36: Mounting | K36: Rear | L36: Right | M36: Bottom | O36: Black | R36: =A36 -> CBC2964 | S36: 55 | T36: 0 | X36: included | AB36: Dismantled from bottom & engine damaged MY1997 XK8 Convertible VIN 0136xx | AC36: =68000*1.61 -> 109480 | AD36: KK | AE36: =S36*D36 -> 55
A37: CBC2965 | B37: Jaguar XK8 XKR X100 | C37: Rear upper link | D37: 1 | E37: STEERING AND SUSPENTION/SUBFRAME AND MOUNTINGS-REAR - Link | H37: Suspention/rear | I37: Mounting | K37: Rear | L37: Left | M37: Bottom | O37: Black | R37: =A37 -> CBC2965 | S37: 55 | T37: 0 | X37: included | AB37: Dismantled from bottom & engine damaged MY1997 XK8 Convertible VIN 0136xx | AC37: =68000*1.61 -> 109480 | AD37: KK | AE37: =S37*D37 -> 55
A38: CBC8207 | B38: Jaguar XK8 XKR X100 | C38: Wheel Bearing - Spacer | E38: STEERING AND SUSPENSION/HUB AND CARRIER-REAR - Bearing Spacer | H38: Spacer | I38: Bearing | K38: Rear | L38: Left/Right | R38: =A38 -> CBC8207 | T38: 0 | AC38: =68000*1.61 -> 109480 | AE38: =S38*D38 -> 0
A39: CCC2890 | B39: Jaguar XK8 XKR X100 | C39: Pendulum | D39: 1 | E39: STEERING AND SUSPENTION/SUSPENSION WISHBONES AND ARMS-REAR - Pendulum | G39: 0241540 | H39: Suspention/rear | I39: Mounting | K39: Rear | L39: Center | M39: Bottom | O39: Black | Q39: Pendulum | R39: =A39 -> CCC2890 | S39: 145 | T39: 0 | X39: included | AB39: Dismantled from bottom & engine damaged MY1997 XK8 Convertible VIN 0136xx | AC39: =68000*1.61 -> 109480 | AD39: KK | AE39: =S39*D39 -> 145
A40: CCC4466 | B40: Jaguar XK8 XKR X100 | C40: Wheel Bearing Seal - Outer | E40: STEERING AND SUSPENSION/HUB AND CARRIER-REAR - Outer Seal | H40: Seal / Insulation | I40: Bearing | K40: Rear | L40: Left/Right | R40: =A40 -> CCC4466 | T40: 0 | AC40: =68000*1.61 -> 109480 | AE40: =S40*D40 -> 0
...

Sheet eBay-TurboLister-2016071
A1: Action(CC=Cp1252) | B1: SiteID | C1: Format | D1: Title | E1: Condition | F1: ConditionDescription | G1: SubTitle | H1: Custom Label | I1: Category | J1: Category2 | K1: StoreCategory | L1: StoreCategory2 | M1: Quantity | N1: LotSize | O1: Currency | P1: StartPrice | Q1: BuyItNowPrice | R1: ReservePrice | S1: Duration | T1: PrivateAuction | U1: Country | V1: ProductIDType | W1: ProductIDValue | X1: Product:ProductReferenceID | Y1: ItemID | Z1: Description | AA1: HitCounter | AB1: PicURL | AC1: BoldTitle | AD1: Featured | AE1: GalleryType | AF1: FeaturedFirstDuration | AG1: Highlight | AH1: Border | AI1: HomePageFeatured | AJ1: Subtitle in search resutls | AK1: GiftIcon | AL1: GiftServices-1 | AM1: GiftServices-2 | AN1: GiftServices-3 | AO1: SalesTaxPercent | AP1: SalesTaxState | AQ1: ShippingInTax | AR1: UseTaxTable | AS1: PostalCode | AT1: ProxyItem | AU1: VATPercent | AV1: Location | AW1: UPC | AX1: ShippingPolicyId | AY1: PaymentPolicyId | AZ1: ReturnPolicyId | BA1: ShippingPolicyName | BB1: PaymentPolicyName | BC1: ReturnPolicyName | BD1: PaymentSeeDescription | BE1: GlobalShippingService | BF1: PickupAndDropOffService | BG1: eBayPlus | BH1: ShipFromZipCode | BI1: ShippingIrregular | BJ1: ShippingPackage | BK1: WeightMajor | BL1: WeightMinor | BM1: WeightUnit | BN1: MeasurementUnit | BO1: PackageLength | BP1: PackageWidth | BQ1: PackageDepth | BR1: CharityID | BS1: CharityName | BT1: DonationPercent | BU1: BasicUpgradePackBundle | BV1: ValuePackBundle | BW1: ProPackPlusBundle | BX1: BestOfferEnabled | BY1: AutoAccept | BZ1: BestOfferAutoAcceptPrice | CA1: AutoDecline | CB1: MinimumBestOfferPrice | CC1: BestOfferRejectMessage | CD1: LocalListingDistance | CE1: BuyerRequirements:ShipToRegCountry | CF1: BuyerRequirements:ZeroFeedbackScore | CG1: BuyerRequirements:MinFeedbackScore | CH1: BuyerRequirements:MaxUnpaidItemsCount | CI1: BuyerRequirements:MaxUnpaidItemsPeriod | CJ1: BuyerRequirements:MaxItemCount | CK1: BuyerRequirements:MaxItemMinFeedback | CL1: BuyerRequirements:LinkedPayPalAccount | CM1: BuyerRequirements:VerifiedUser | CN1: BuyerRequirements:VerifiedUserScore | CO1: BuyerRequirements:MaxViolationCount | CP1: BuyerRequirements:MaxViolationPeriod | CQ1: SellerDetails:PrimaryPhone | CR1: SellerDetails:SecondaryPhone | CS1: ExtSellerDetails:Hours1Days | CT1: ExtSellerDetails:Hours1AnyTime | CU1: ExtSellerDetails:Hours1From | CV1: ExtSellerDetails:Hours1To | CW1: ExtSellerDetails:Hours2Days | CX1: ExtSellerDetails:Hours2AnyTime | CY1: ExtSellerDetails:Hours2From | CZ1: ExtSellerDetails:Hours2To | DA1: ExtSellerDetails:TimeZoneID | DB1: ListingDesigner:LayoutID | DC1: ListingDesigner:ThemeID | DD1: ShippingDiscountProfileID | DE1: InternationalShippingDiscountProfileID | DF1: PromoteCBT | DG1: CustomLabel | DH1: ReturnsRestockingFee | DI1: ExtendedHolidayReturns | DJ1: MarketplaceType | DK1: ProjectGoodCategory | DL1: ShortDescription | DM1: ProducerDescription | DN1: RegionOfOrigin | DO1: ProducerPhotoURL | DP1: C:Brand | DQ1: C:Manufacturer Part Number | DR1: C:Classic Car Part | DS1: C:Placement on Vehicle | DT1: Relationship | DU1: RelationshipDetails
A2: Add | B2: UK | C2: FixedPriceItem | D2: =PartsMaster!B406&" "&PartsMaster!$C406 -> Jaguar XK8 XKR X100 Seat - Mechanism cover - Warm Charcoal | E2: 3000 | F2: Normal Used Condition. | H2: =PartsMaster!$Q406 -> 0 | I2: 9886 | K2: 0 | L2: 0 | M2: =PartsMaster!$D406 -> 0 | O2: GBP | P2: =PartsMaster!$S406/1.45 -> 0 | S2: 30 | T2: 0 | U2: EE | Z2: ="<P>"&PartsMaster!$I406&" "&PartsMaster!$H406&"</P>"&"<P>Jaguar part name "&PartsMaster!$E406&"</P><P>Product numbers "&PartsMaster!R406&" "&DQ2&"</P><P>Fits starting from VIN/ModelYear "&PartsMaster!$F406&" until VIN/ModelYear "&PartsMaster!$G406&"</P><P>Condition: "&PartsMaster!AB406&"</P><P> (part source "&PartsMaster!AD406&")</P><P>Notes: "&PartsMaster!AA406&"</P>" -> <P>Cap / Cover Cap / Cover / Trim</P><P>Jaguar part name </P><P>Product numbers 0</P><P>Fits starting from VIN/ModelYear until VIN/ModelYear </P><P>Condition: </P><P> (part source )</P><P>Notes: </P> | AA2: BasicStyle | AC2: 0 | AD2: 0 | AE2: None | AF2: 7 | AG2: 0 | AH2: 0 | AI2: 0 | AJ2: 0 | AK2: 0 | AO2: 0.00 | AR2: 0 | AS2: 10112 | AV2: Tallinn | AX2: 62128510024 | AY2: 62035811024 | AZ2: 55187694024 | BA2: Shipping per agreement | BB2: PayPal:Immediate pay | BC2: Return Policy | BD2: 1 | BE2: 0 | BF2: 0 | BG2: 0 | BN2: Metric | BV2: 0 | CL2: 0 | DD2: 0|287377024| | DE2: 0|287377024| | DI2: 0 | DP2: Jaguar | DQ2: =PartsMaster!$A406 -> 0 | DR2: Yes | DS2: =PartsMaster!$K407&" "&PartsMaster!L407&" "&PartsMaster!$M407 -> Front Right Low
A3: Add | B3: UK | C3: FixedPriceItem | D3: =PartsMaster!B407&" "&PartsMaster!$C407 -> Jaguar XK8 XKR X100 Seat - Mechanism cover - Warm Charcoal | E3: 3000 | F3: Normal Used Condition. | H3: =PartsMaster!$Q407 -> 0 | I3: 9886 | K3: 0 | L3: 0 | M3: =PartsMaster!$D407 -> 0 | O3: GBP | P3: =PartsMaster!$S407/1.45 -> 0 | S3: 30 | T3: 0 | U3: EE | Z3: ="<P>"&PartsMaster!$I407&" "&PartsMaster!$H407&"</P>"&"<P>Jaguar part name "&PartsMaster!$E407&"</P><P>Product numbers "&PartsMaster!R407&" "&DQ3&"</P><P>Fits starting from VIN/ModelYear "&PartsMaster!$F407&" until VIN/ModelYear "&PartsMaster!$G407&"</P><P>Condition: "&PartsMaster!AB407&"</P><P> (part source "&PartsMaster!AD407&")</P><P>Notes: "&PartsMaster!AA407&"</P>" -> <P>Cap / Cover Cap / Cover / Trim</P><P>Jaguar part name </P><P>Product numbers 0</P><P>Fits starting from VIN/ModelYear until VIN/ModelYear </P><P>Condition: </P><P> (part source )</P><P>Notes: </P> | AA3: BasicStyle | AC3: 0 | AD3: 0 | AE3: None | AF3: 7 | AG3: 0 | AH3: 0 | AI3: 0 | AJ3: 0 | AK3: 0 | AO3: 0.00 | AR3: 0 | AS3: 10112 | AV3: Tallinn | AX3: 62128510024 | AY3: 62035811024 | AZ3: 55187694024 | BA3: Shipping per agreement | BB3: PayPal:Immediate pay | BC3: Return Policy | BD3: 1 | BE3: 0 | BF3: 0 | BG3: 0 | BN3: Metric | BV3: 0 | CL3: 0 | DD3: 0|287377024| | DE3: 0|287377024| | DI3: 0 | DP3: Jaguar | DQ3: =PartsMaster!$A407 -> 0 | DR3: Yes | DS3: =PartsMaster!$K408&" "&PartsMaster!L408&" "&PartsMaster!$M408 -> Front Right Low
A4: Add | B4: UK | C4: FixedPriceItem | D4: =PartsMaster!B2&" "&PartsMaster!$C2 -> Jaguar XK8 XKR X100 Timing Chain Service Kit (no Crank Bold) | E4: 3000 | F4: Normal Used Condition. | H4: =PartsMaster!$Q2 -> TIMING GEAR SERVICE KIT | I4: 9886 | K4: 0 | L4: 0 | M4: =PartsMaster!$D2 -> 0 | O4: GBP | P4: =PartsMaster!$S2/1.45 -> 0 | S4: 30 | T4: 0 | U4: EE | Z4: ="<P>"&PartsMaster!$I2&" "&PartsMaster!$H2&"</P>"&"<P>Jaguar part name "&PartsMaster!$E2&"</P><P>Product numbers "&PartsMaster!R2&" "&DQ4&"</P><P>Fits starting from VIN/ModelYear "&PartsMaster!$F2&" until VIN/ModelYear "&PartsMaster!$G2&"</P><P>Condition: "&PartsMaster!AB2&"</P><P> (part source "&PartsMaster!AD2&")</P><P>Notes: "&PartsMaster!AA2&"</P>" -> <P>Engine Timing Kit</P><P>Jaguar part name </P><P>Product numbers ACC1269KIT ACC1269KIT</P><P>Fits starting from VIN/ModelYear until VIN/ModelYear </P><P>Condition: British Parts</P><P> (part source )</P><P>Notes: </P> | AA4: BasicStyle | AC4: 0 | AD4: 0 | AE4: None | AF4: 7 | AG4: 0 | AH4: 0 | AI4: 0 | AJ4: 0 | AK4: 0 | AO4: 0.00 | AR4: 0 | AS4: 10112 | AV4: Tallinn | AX4: 62128510024 | AY4: 62035811024 | AZ4: 55187694024 | BA4: Shipping per agreement | BB4: PayPal:Immediate pay | BC4: Return Policy | BD4: 1 | BE4: 0 | BF4: 0 | BG4: 0 | BN4: Metric | BV4: 0 | CL4: 0 | DD4: 0|287377024| | DE4: 0|287377024| | DI4: 0 | DP4: Jaguar | DQ4: =PartsMaster!$A2 -> ACC1269KIT | DR4: Yes | DS4: =PartsMaster!$K3&" "&PartsMaster!L3&" "&PartsMaster!$M3 -> Front/Rear Left/Right
A5: Add | B5: UK | C5: FixedPriceItem | D5: =PartsMaster!B3&" "&PartsMaster!$C3 -> Jaguar XK8 XKR X100 Wheelarch Liner - Plastic push on nut | E5: 3000 | F5: Normal Used Condition. | H5: =PartsMaster!$Q3 -> NUT-PLASTIC | I5: 9886 | K5: 0 | L5: 0 | M5: =PartsMaster!$D3 -> 0 | O5: GBP | P5: =PartsMaster!$S3/1.45 -> 0 | S5: 30 | T5: 0 | U5: EE | Z5: ="<P>"&PartsMaster!$I3&" "&PartsMaster!$H3&"</P>"&"<P>Jaguar part name "&PartsMaster!$E3&"</P><P>Product numbers "&PartsMaster!R3&" "&DQ5&"</P><P>Fits starting from VIN/ModelYear "&PartsMaster!$F3&" until VIN/ModelYear "&PartsMaster!$G3&"</P><P>Condition: "&PartsMaster!AB3&"</P><P> (part source "&PartsMaster!AD3&")</P><P>Notes: "&PartsMaster!AA3&"</P>" -> <P>Mounting Bolt / Screw</P><P>Jaguar part name </P><P>Product numbers AGU2436J AGU2436J</P><P>Fits starting from VIN/ModelYear until VIN/ModelYear </P><P>Condition: SNG Barratt</P><P> (part source )</P><P>Notes: </P> | AA5: BasicStyle | AC5: 0 | AD5: 0 | AE5: None | AF5: 7 | AG5: 0 | AH5: 0 | AI5: 0 | AJ5: 0 | AK5: 0 | AO5: 0.00 | AR5: 0 | AS5: 10112 | AV5: Tallinn | AX5: 62128510024 | AY5: 62035811024 | AZ5: 55187694024 | BA5: Shipping per agreement | BB5: PayPal:Immediate pay | BC5: Return Policy | BD5: 1 | BE5: 0 | BF5: 0 | BG5: 0 | BN5: Metric | BV5: 0 | CL5: 0 | DD5: 0|287377024| | DE5: 0|287377024| | DI5: 0 | DP5: Jaguar | DQ5: =PartsMaster!$A3 -> AGU2436J | DR5: Yes | DS5: =PartsMaster!$K4&" "&PartsMaster!L4&" "&PartsMaster!$M4 -> Rear Top
A6: Add | B6: UK | C6: FixedPriceItem | D6: =PartsMaster!B408&" "&PartsMaster!$C408 -> Jaguar XK8 XKR X100 Seat - Mechanism cover - Warm Charcoal | E6: 3000 | F6: Normal Used Condition. | H6: =PartsMaster!$Q408 -> 0 | I6: 9886 | K6: 0 | L6: 0 | M6: =PartsMaster!$D408 -> 0 | O6: GBP | P6: =PartsMaster!$S408/1.45 -> 0 | S6: 30 | T6: 0 | U6: EE | Z6: ="<P>"&PartsMaster!$I408&" "&PartsMaster!$H408&"</P>"&"<P>Jaguar part name "&PartsMaster!$E408&"</P><P>Product numbers "&PartsMaster!R408&" "&DQ6&"</P><P>Fits starting from VIN/ModelYear "&PartsMaster!$F408&" until VIN/ModelYear "&PartsMaster!$G408&"</P><P>Condition: "&PartsMaster!AB408&"</P><P> (part source "&PartsMaster!AD408&")</P><P>Notes: "&PartsMaster!AA408&"</P>" -> <P>Cap / Cover Cap / Cover / Trim</P><P>Jaguar part name </P><P>Product numbers 0</P><P>Fits starting from VIN/ModelYear until VIN/ModelYear </P><P>Condition: </P><P> (part source )</P><P>Notes: </P> | AA6: BasicStyle | AC6: 0 | AD6: 0 | AE6: None | AF6: 7 | AG6: 0 | AH6: 0 | AI6: 0 | AJ6: 0 | AK6: 0 | AO6: 0.00 | AR6: 0 | AS6: 10112 | AV6: Tallinn | AX6: 62128510024 | AY6: 62035811024 | AZ6: 55187694024 | BA6: Shipping per agreement | BB6: PayPal:Immediate pay | BC6: Return Policy | BD6: 1 | BE6: 0 | BF6: 0 | BG6: 0 | BN6: Metric | BV6: 0 | CL6: 0 | DD6: 0|287377024| | DE6: 0|287377024| | DI6: 0 | DP6: Jaguar | DQ6: =PartsMaster!$A408 -> 0 | DR6: Yes | DS6: =PartsMaster!$K409&" "&PartsMaster!L409&" "&PartsMaster!$M409 -> Front Right Low
A7: Add | B7: UK | C7: FixedPriceItem | D7: =PartsMaster!B4&" "&PartsMaster!$C4 -> Jaguar XK8 XKR X100 Trunk lining mount rivets | E7: 3000 | F7: Normal Used Condition. | H7: =PartsMaster!$Q4 -> FASTENER-PUS | I7: 9886 | K7: 0 | L7: 0 | M7: =PartsMaster!$D4 -> 6 | O7: GBP | P7: =PartsMaster!$S4/1.45 -> 0.68965517 | S7: 30 | T7: 0 | U7: EE | Z7: ="<P>"&PartsMaster!$I4&" "&PartsMaster!$H4&"</P>"&"<P>Jaguar part name "&PartsMaster!$E4&"</P><P>Product numbers "&PartsMaster!R4&" "&DQ7&"</P><P>Fits starting from VIN/ModelYear "&PartsMaster!$F4&" until VIN/ModelYear "&PartsMaster!$G4&"</P><P>Condition: "&PartsMaster!AB4&"</P><P> (part source "&PartsMaster!AD4&")</P><P>Notes: "&PartsMaster!AA4&"</P>" -> <P>Fastener / Fir-tree / Rivet Interior trim</P><P>Jaguar part name Trunc Lid Liner Push in fastener </P><P>Product numbers AGU2530 AGU2530</P><P>Fits starting from VIN/ModelYear until VIN/ModelYear </P><P>Condition: Dismantled from bottom & engine damaged MY1997 XK8 Convertible VIN 0136xx</P><P> (part source )</P><P>Notes: </P> | AA7: BasicStyle | AC7: 0 | AD7: 0 | AE7: None | AF7: 7 | AG7: 0 | AH7: 0 | AI7: 0 | AJ7: 0 | AK7: 0 | AO7: 0.00 | AR7: 0 | AS7: 10112 | AV7: Tallinn | AX7: 62128510024 | AY7: 62035811024 | AZ7: 55187694024 | BA7: Shipping per agreement | BB7: PayPal:Immediate pay | BC7: Return Policy | BD7: 1 | BE7: 0 | BF7: 0 | BG7: 0 | BN7: Metric | BV7: 0 | CL7: 0 | DD7: 0|287377024| | DE7: 0|287377024| | DI7: 0 | DP7: Jaguar | DQ7: =PartsMaster!$A4 -> AGU2530 | DR7: Yes | DS7: =PartsMaster!$K5&" "&PartsMaster!L5&" "&PartsMaster!$M5
A8: Add | B8: UK | C8: FixedPriceItem | D8: =PartsMaster!B5&" "&PartsMaster!$C5 -> Jaguar XK8 XKR X100 THERMOSTAT KIT-ALUMINIUM | E8: 3000 | F8: Normal Used Condition. | H8: =PartsMaster!$Q5 -> THERMOSTAT KIT-ALUMINIUM | I8: 9886 | K8: 0 | L8: 0 | M8: =PartsMaster!$D5 -> 0 | O8: GBP | P8: =PartsMaster!$S5/1.45 -> 0 | S8: 30 | T8: 0 | U8: EE | Z8: ="<P>"&PartsMaster!$I5&" "&PartsMaster!$H5&"</P>"&"<P>Jaguar part name "&PartsMaster!$E5&"</P><P>Product numbers "&PartsMaster!R5&" "&DQ8&"</P><P>Fits starting from VIN/ModelYear "&PartsMaster!$F5&" until VIN/ModelYear "&PartsMaster!$G5&"</P><P>Condition: "&PartsMaster!AB5&"</P><P> (part source "&PartsMaster!AD5&")</P><P>Notes: "&PartsMaster!AA5&"</P>" -> <P>Engine Cooling Kit</P><P>Jaguar part name </P><P>Product numbers AJ82217KIT1A AJ82217KIT1A</P><P>Fits starting from VIN/ModelYear until VIN/ModelYear </P><P>Condition: British Parts</P><P> (part source )</P><P>Notes: </P> | AA8: BasicStyle | AC8: 0 | AD8: 0 | AE8: None | AF8: 7 | AG8: 0 | AH8: 0 | AI8: 0 | AJ8: 0 | AK8: 0 | AO8: 0.00 | AR8: 0 | AS8: 10112 | AV8: Tallinn | AX8: 62128510024 | AY8: 62035811024 | AZ8: 55187694024 | BA8: Shipping per agreement | BB8: PayPal:Immediate pay | BC8: Return Policy | BD8: 1 | BE8: 0 | BF8: 0 | BG8: 0 | BN8: Metric | BV8: 0 | CL8: 0 | DD8: 0|287377024| | DE8: 0|287377024| | DI8: 0 | DP8: Jaguar | DQ8: =PartsMaster!$A5 -> AJ82217KIT1A | DR8: Yes | DS8: =PartsMaster!$K6&" "&PartsMaster!L6&" "&PartsMaster!$M6
A9: Add | B9: UK | C9: FixedPriceItem | D9: =PartsMaster!B6&" "&PartsMaster!$C6 -> Jaguar XK8 XKR X100 Timing Chain Tensioner Primary | E9: 3000 | F9: Normal Used Condition. | H9: =PartsMaster!$Q6 -> TIMING CHAIN TENSIONER | I9: 9886 | K9: 0 | L9: 0 | M9: =PartsMaster!$D6 -> 1 | O9: GBP | P9: =PartsMaster!$S6/1.45 -> 0 | S9: 30 | T9: 0 | U9: EE | Z9: ="<P>"&PartsMaster!$I6&" "&PartsMaster!$H6&"</P>"&"<P>Jaguar part name "&PartsMaster!$E6&"</P><P>Product numbers "&PartsMaster!R6&" "&DQ9&"</P><P>Fits starting from VIN/ModelYear "&PartsMaster!$F6&" until VIN/ModelYear "&PartsMaster!$G6&"</P><P>Condition: "&PartsMaster!AB6&"</P><P> (part source "&PartsMaster!AD6&")</P><P>Notes: "&PartsMaster!AA6&"</P>" -> <P>Engine Timing Chain tensioner</P><P>Jaguar part name </P><P>Product numbers AJ82325 AJ82325</P><P>Fits starting from VIN/ModelYear X100, 1996 - X308, 1997 until VIN/ModelYear X100, 2006 - X308, 2002</P><P>Condition: British Parts</P><P> (part source )</P><P>Notes: </P> | AA9: BasicStyle | AC9: 0 | AD9: 0 | AE9: None | AF9: 7 | AG9: 0 | AH9: 0 | AI9: 0 | AJ9: 0 | AK9: 0 | AO9: 0.00 | AR9: 0 | AS9: 10112 | AV9: Tallinn | AX9: 62128510024 | AY9: 62035811024 | AZ9: 55187694024 | BA9: Shipping per agreement | BB9: PayPal:Immediate pay | BC9: Return Policy | BD9: 1 | BE9: 0 | BF9: 0 | BG9: 0 | BN9: Metric | BV9: 0 | CL9: 0 | DD9: 0|287377024| | DE9: 0|287377024| | DI9: 0 | DP9: Jaguar | DQ9: =PartsMaster!$A6 -> AJ82325 | DR9: Yes | DS9: =PartsMaster!$K7&" "&PartsMaster!L7&" "&PartsMaster!$M7
A10: Add | B10: UK | C10: FixedPriceItem | D10: =PartsMaster!B7&" "&PartsMaster!$C7 -> Jaguar XK8 XKR X100 CAMSHAFT COVER SEAL-VVT | E10: 3000 | F10: Normal Used Condition. | H10: =PartsMaster!$Q7 -> CAMSHAFT COVER SEAL-VVT | I10: 9886 | K10: 0 | L10: 0 | M10: =PartsMaster!$D7 -> 0 | O10: GBP | P10: =PartsMaster!$S7/1.45 -> 0 | S10: 30 | T10: 0 | U10: EE | Z10: ="<P>"&PartsMaster!$I7&" "&PartsMaster!$H7&"</P>"&"<P>Jaguar part name "&PartsMaster!$E7&"</P><P>Product numbers "&PartsMaster!R7&" "&DQ10&"</P><P>Fits starting from VIN/ModelYear "&PartsMaster!$F7&" until VIN/ModelYear "&PartsMaster!$G7&"</P><P>Condition: "&PartsMaster!AB7&"</P><P> (part source "&PartsMaster!AD7&")</P><P>Notes: "&PartsMaster!AA7&"</P>" -> <P>Engine Oil Gasket / Seal / O-Ring</P><P>Jaguar part name </P><P>Product numbers AJ82856 AJ82856</P><P>Fits starting from VIN/ModelYear until VIN/ModelYear </P><P>Condition: British Parts</P><P> (part source )</P><P>Notes: </P> | AA10: BasicStyle | AC10: 0 | AD10: 0 | AE10: None | AF10: 7 | AG10: 0 | AH10: 0 | AI10: 0 | AJ10: 0 | AK10: 0 | AO10: 0.00 | AR10: 0 | AS10: 10112 | AV10: Tallinn | AX10: 62128510024 | AY10: 62035811024 | AZ10: 55187694024 | BA10: Shipping per agreement | BB10: PayPal:Immediate pay | BC10: Return Policy | BD10: 1 | BE10: 0 | BF10: 0 | BG10: 0 | BN10: Metric | BV10: 0 | CL10: 0 | DD10: 0|287377024| | DE10: 0|287377024| | DI10: 0 | DP10: Jaguar | DQ10: =PartsMaster!$A7 -> AJ82856 | DR10: Yes | DS10: =PartsMaster!$K8&" "&PartsMaster!L8&" "&PartsMaster!$M8
A11: Add | B11: UK | C11: FixedPriceItem | D11: =PartsMaster!B8&" "&PartsMaster!$C8 -> Jaguar XK8 XKR X100 XJ8 XJR X308 Seal Camshaft Cover VVT | E11: 3000 | F11: Normal Used Condition. | H11: =PartsMaster!$Q8 -> 0 | I11: 9886 | K11: 0 | L11: 0 | M11: =PartsMaster!$D8 -> 0 | O11: GBP | P11: =PartsMaster!$S8/1.45 -> 0 | S11: 30 | T11: 0 | U11: EE | Z11: ="<P>"&PartsMaster!$I8&" "&PartsMaster!$H8&"</P>"&"<P>Jaguar part name "&PartsMaster!$E8&"</P><P>Product numbers "&PartsMaster!R8&" "&DQ11&"</P><P>Fits starting from VIN/ModelYear "&PartsMaster!$F8&" until VIN/ModelYear "&PartsMaster!$G8&"</P><P>Condition: "&PartsMaster!AB8&"</P><P> (part source "&PartsMaster!AD8&")</P><P>Notes: "&PartsMaster!AA8&"</P>" -> <P> Seal / Insulation</P><P>Jaguar part name </P><P>Product numbers AJ82856 AJ82856</P><P>Fits starting from VIN/ModelYear X100, 1996 - X308, 1997 until VIN/ModelYear X100, 2006 - X308, 2002</P><P>Condition: </P><P> (part source )</P><P>Notes: </P> | AA11: BasicStyle | AC11: 0 | AD11: 0 | AE11: None | AF11: 7 | AG11: 0 | AH11: 0 | AI11: 0 | AJ11: 0 | AK11: 0 | AO11: 0.00 | AR11: 0 | AS11: 10112 | AV11: Tallinn | AX11: 62128510024 | AY11: 62035811024 | AZ11: 55187694024 | BA11: Shipping per agreement | BB11: PayPal:Immediate pay | BC11: Return Policy | BD11: 1 | BE11: 0 | BF11: 0 | BG11: 0 | BN11: Metric | BV11: 0 | CL11: 0 | DD11: 0|287377024| | DE11: 0|287377024| | DI11: 0 | DP11: Jaguar | DQ11: =PartsMaster!$A8 -> AJ82856 | DR11: Yes | DS11: =PartsMaster!$K9&" "&PartsMaster!L9&" "&PartsMaster!$M9
A12: Add | B12: UK | C12: FixedPriceItem | D12: =PartsMaster!B9&" "&PartsMaster!$C9 -> Jaguar XK8 XKR X100 OIL SEAL-CRANKSHAFT | E12: 3000 | F12: Normal Used Condition. | H12: =PartsMaster!$Q9 -> OIL SEAL-CRANKSHAFT | I12: 9886 | K12: 0 | L12: 0 | M12: =PartsMaster!$D9 -> 0 | O12: GBP | P12: =PartsMaster!$S9/1.45 -> 0 | S12: 30 | T12: 0 | U12: EE | Z12: ="<P>"&PartsMaster!$I9&" "&PartsMaster!$H9&"</P>"&"<P>Jaguar part name "&PartsMaster!$E9&"</P><P>Product numbers "&PartsMaster!R9&" "&DQ12&"</P><P>Fits starting from VIN/ModelYear "&PartsMaster!$F9&" until VIN/ModelYear "&PartsMaster!$G9&"</P><P>Condition: "&PartsMaster!AB9&"</P><P> (part source "&PartsMaster!AD9&")</P><P>Notes: "&PartsMaster!AA9&"</P>" -> <P>Engine Oil Gasket / Seal / O-Ring</P><P>Jaguar part name </P><P>Product numbers AJ83698 AJ83698</P><P>Fits starting from VIN/ModelYear until VIN/ModelYear </P><P>Condition: British Parts</P><P> (part source )</P><P>Notes: </P> | AA12: BasicStyle | AC12: 0 | AD12: 0 | AE12: None | AF12: 7 | AG12: 0 | AH12: 0 | AI12: 0 | AJ12: 0 | AK12: 0 | AO12: 0.00 | AR12: 0 | AS12: 10112 | AV12: Tallinn | AX12: 62128510024 | AY12: 62035811024 | AZ12: 55187694024 | BA12: Shipping per agreement | BB12: PayPal:Immediate pay | BC12: Return Policy | BD12: 1 | BE12: 0 | BF12: 0 | BG12: 0 | BN12: Metric | BV12: 0 | CL12: 0 | DD12: 0|287377024| | DE12: 0|287377024| | DI12: 0 | DP12: Jaguar | DQ12: =PartsMaster!$A9 -> AJ83698 | DR12: Yes | DS12: =PartsMaster!$K10&" "&PartsMaster!L10&" "&PartsMaster!$M10
A13: Add | B13: UK | C13: FixedPriceItem | D13: =PartsMaster!B10&" "&PartsMaster!$C10 -> Jaguar XK8 XKR X100 XJ8 XJR X308 Timing Cover Seal Inner | E13: 3000 | F13: Normal Used Condition. | H13: =PartsMaster!$Q10 -> Timing Cover Seal Inner | I13: 9886 | K13: 0 | L13: 0 | M13: =PartsMaster!$D10 -> 0 | O13: GBP | P13: =PartsMaster!$S10/1.45 -> 0 | S13: 30 | T13: 0 | U13: EE | Z13: ="<P>"&PartsMaster!$I10&" "&PartsMaster!$H10&"</P>"&"<P>Jaguar part name "&PartsMaster!$E10&"</P><P>Product numbers "&PartsMaster!R10&" "&DQ13&"</P><P>Fits starting from VIN/ModelYear "&PartsMaster!$F10&" until VIN/ModelYear "&PartsMaster!$G10&"</P><P>Condition: "&PartsMaster!AB10&"</P><P> (part source "&PartsMaster!AD10&")</P><P>Notes: "&PartsMaster!AA10&"</P>" -> <P>Engine timing Gasket / Seal / O-Ring</P><P>Jaguar part name </P><P>Product numbers AJ83699 AJ83699</P><P>Fits starting from VIN/ModelYear X100, 1996 - X308, 1997 until VIN/ModelYear X100, 2006 - X308, 2002</P><P>Condition: </P><P> (part source )</P><P>Notes: </P> | AA13: BasicStyle | AC13: 0 | AD13: 0 | AE13: None | AF13: 7 | AG13: 0 | AH13: 0 | AI13: 0 | AJ13: 0 | AK13: 0 | AO13: 0.00 | AR13: 0 | AS13: 10112 | AV13: Tallinn | AX13: 62128510024 | AY13: 62035811024 | AZ13: 55187694024 | BA13: Shipping per agreement | BB13: PayPal:Immediate pay | BC13: Return Policy | BD13: 1 | BE13: 0 | BF13: 0 | BG13: 0 | BN13: Metric | BV13: 0 | CL13: 0 | DD13: 0|287377024| | DE13: 0|287377024| | DI13: 0 | DP13: Jaguar | DQ13: =PartsMaster!$A10 -> AJ83699 | DR13: Yes | DS13: =PartsMaster!$K11&" "&PartsMaster!L11&" "&PartsMaster!$M11
A14: Add | B14: UK | C14: FixedPriceItem | D14: =PartsMaster!B11&" "&PartsMaster!$C11 -> Jaguar XK8 XKR X100 Crankshaft Oil Seal | E14: 3000 | F14: Normal Used Condition. | H14: =PartsMaster!$Q11 -> OIL SEAL-CRANKSHAFT | I14: 9886 | K14: 0 | L14: 0 | M14: =PartsMaster!$D11 -> 0 | O14: GBP | P14: =PartsMaster!$S11/1.45 -> 0 | S14: 30 | T14: 0 | U14: EE | Z14: ="<P>"&PartsMaster!$I11&" "&PartsMaster!$H11&"</P>"&"<P>Jaguar part name "&PartsMaster!$E11&"</P><P>Product numbers "&PartsMaster!R11&" "&DQ14&"</P><P>Fits starting from VIN/ModelYear "&PartsMaster!$F11&" until VIN/ModelYear "&PartsMaster!$G11&"</P><P>Condition: "&PartsMaster!AB11&"</P><P> (part source "&PartsMaster!AD11&")</P><P>Notes: "&PartsMaster!AA11&"</P>" -> <P>Engine Oil Gasket / Seal / O-Ring</P><P>Jaguar part name </P><P>Product numbers AJ83744 AJ83744</P><P>Fits starting from VIN/ModelYear until VIN/ModelYear </P><P>Condition: British Parts</P><P> (part source )</P><P>Notes: </P> | AA14: BasicStyle | AC14: 0 | AD14: 0 | AE14: None | AF14: 7 | AG14: 0 | AH14: 0 | AI14: 0 | AJ14: 0 | AK14: 0 | AO14: 0.00 | AR14: 0 | AS14: 10112 | AV14: Tallinn | AX14: 62128510024 | AY14: 62035811024 | AZ14: 55187694024 | BA14: Shipping per agreement | BB14: PayPal:Immediate pay | BC14: Return Policy | BD14: 1 | BE14: 0 | BF14: 0 | BG14: 0 | BN14: Metric | BV14: 0 | CL14: 0 | DD14: 0|287377024| | DE14: 0|287377024| | DI14: 0 | DP14: Jaguar | DQ14: =PartsMaster!$A11 -> AJ83744 | DR14: Yes | DS14: =PartsMaster!$K12&" "&PartsMaster!L12&" "&PartsMaster!$M12
A15: Add | B15: UK | C15: FixedPriceItem | D15: =PartsMaster!B12&" "&PartsMaster!$C12 -> Jaguar XK8 XKR X100 THERMOSTAT | E15: 3000 | F15: Normal Used Condition. | H15: =PartsMaster!$Q12 -> THERMOSTAT | I15: 9886 | K15: 0 | L15: 0 | M15: =PartsMaster!$D12 -> 0 | O15: GBP | P15: =PartsMaster!$S12/1.45 -> 0 | S15: 30 | T15: 0 | U15: EE | Z15: ="<P>"&PartsMaster!$I12&" "&PartsMaster!$H12&"</P>"&"<P>Jaguar part name "&PartsMaster!$E12&"</P><P>Product numbers "&PartsMaster!R12&" "&DQ15&"</P><P>Fits starting from VIN/ModelYear "&PartsMaster!$F12&" until VIN/ModelYear "&PartsMaster!$G12&"</P><P>Condition: "&PartsMaster!AB12&"</P><P> (part source "&PartsMaster!AD12&")</P><P>Notes: "&PartsMaster!AA12&"</P>" -> <P>Engine Cooling Switch </P><P>Jaguar part name </P><P>Product numbers AJ86484 AJ86484</P><P>Fits starting from VIN/ModelYear until VIN/ModelYear </P><P>Condition: British Parts</P><P> (part source )</P><P>Notes: </P> | AA15: BasicStyle | AC15: 0 | AD15: 0 | AE15: None | AF15: 7 | AG15: 0 | AH15: 0 | AI15: 0 | AJ15: 0 | AK15: 0 | AO15: 0.00 | AR15: 0 | AS15: 10112 | AV15: Tallinn | AX15: 62128510024 | AY15: 62035811024 | AZ15: 55187694024 | BA15: Shipping per agreement | BB15: PayPal:Immediate pay | BC15: Return Policy | BD15: 1 | BE15: 0 | BF15: 0 | BG15: 0 | BN15: Metric | BV15: 0 | CL15: 0 | DD15: 0|287377024| | DE15: 0|287377024| | DI15: 0 | DP15: Jaguar | DQ15: =PartsMaster!$A12 -> AJ86484 | DR15: Yes | DS15: =PartsMaster!$K13&" "&PartsMaster!L13&" "&PartsMaster!$M13
A16: Add | B16: UK | C16: FixedPriceItem | D16: =PartsMaster!B13&" "&PartsMaster!$C13 -> Jaguar XK8 XKR X100 CAMSHAFT COVER CENTRE SEAL | E16: 3000 | F16: Normal Used Condition. | H16: =PartsMaster!$Q13 -> CAMSHAFT COVER CENTRE SEAL | I16: 9886 | K16: 0 | L16: 0 | M16: =PartsMaster!$D13 -> 0 | O16: GBP | P16: =PartsMaster!$S13/1.45 -> 0 | S16: 30 | T16: 0 | U16: EE | Z16: ="<P>"&PartsMaster!$I13&" "&PartsMaster!$H13&"</P>"&"<P>Jaguar part name "&PartsMaster!$E13&"</P><P>Product numbers "&PartsMaster!R13&" "&DQ16&"</P><P>Fits starting from VIN/ModelYear "&PartsMaster!$F13&" until VIN/ModelYear "&PartsMaster!$G13&"</P><P>Condition: "&PartsMaster!AB13&"</P><P> (part source "&PartsMaster!AD13&")</P><P>Notes: "&PartsMaster!AA13&"</P>" -> <P>Engine Oil Gasket / Seal / O-Ring</P><P>Jaguar part name </P><P>Product numbers AJ87242 AJ87242</P><P>Fits starting from VIN/ModelYear until VIN/ModelYear </P><P>Condition: British Parts</P><P> (part source )</P><P>Notes: </P> | AA16: BasicStyle | AC16: 0 | AD16: 0 | AE16: None | AF16: 7 | AG16: 0 | AH16: 0 | AI16: 0 | AJ16: 0 | AK16: 0 | AO16: 0.00 | AR16: 0 | AS16: 10112 | AV16: Tallinn | AX16: 62128510024 | AY16: 62035811024 | AZ16: 55187694024 | BA16: Shipping per agreement | BB16: PayPal:Immediate pay | BC16: Return Policy | BD16: 1 | BE16: 0 | BF16: 0 | BG16: 0 | BN16: Metric | BV16: 0 | CL16: 0 | DD16: 0|287377024| | DE16: 0|287377024| | DI16: 0 | DP16: Jaguar | DQ16: =PartsMaster!$A13 -> AJ87242 | DR16: Yes | DS16: =PartsMaster!$K14&" "&PartsMaster!L14&" "&PartsMaster!$M14 -> Left
A17: Add | B17: UK | C17: FixedPriceItem | D17: =PartsMaster!B14&" "&PartsMaster!$C14 -> Jaguar XK8 XKR X100 XJ8 XJR X308 Gasket Camshaft Cover B-Bank | E17: 3000 | F17: Normal Used Condition. | H17: =PartsMaster!$Q14 -> Cam Cover Gasket LH B Bank | I17: 9886 | K17: 0 | L17: 0 | M17: =PartsMaster!$D14 -> 0 | O17: GBP | P17: =PartsMaster!$S14/1.45 -> 14.482759 | S17: 30 | T17: 0 | U17: EE | Z17: ="<P>"&PartsMaster!$I14&" "&PartsMaster!$H14&"</P>"&"<P>Jaguar part name "&PartsMaster!$E14&"</P><P>Product numbers "&PartsMaster!R14&" "&DQ17&"</P><P>Fits starting from VIN/ModelYear "&PartsMaster!$F14&" until VIN/ModelYear "&PartsMaster!$G14&"</P><P>Condition: "&PartsMaster!AB14&"</P><P> (part source "&PartsMaster!AD14&")</P><P>Notes: "&PartsMaster!AA14&"</P>" -> <P> Gasket / Seal / O-Ring</P><P>Jaguar part name </P><P>Product numbers AJ88285 AJ88285</P><P>Fits starting from VIN/ModelYear Engine #9810290000 until VIN/ModelYear </P><P>Condition: </P><P> (part source )</P><P>Notes: </P> | AA17: BasicStyle | AC17: 0 | AD17: 0 | AE17: None | AF17: 7 | AG17: 0 | AH17: 0 | AI17: 0 | AJ17: 0 | AK17: 0 | AO17: 0.00 | AR17: 0 | AS17: 10112 | AV17: Tallinn | AX17: 62128510024 | AY17: 62035811024 | AZ17: 55187694024 | BA17: Shipping per agreement | BB17: PayPal:Immediate pay | BC17: Return Policy | BD17: 1 | BE17: 0 | BF17: 0 | BG17: 0 | BN17: Metric | BV17: 0 | CL17: 0 | DD17: 0|287377024| | DE17: 0|287377024| | DI17: 0 | DP17: Jaguar | DQ17: =PartsMaster!$A14 -> AJ88285 | DR17: Yes | DS17: =PartsMaster!$K15&" "&PartsMaster!L15&" "&PartsMaster!$M15 -> Right
A18: Add | B18: UK | C18: FixedPriceItem | D18: =PartsMaster!B15&" "&PartsMaster!$C15 -> Jaguar XK8 XKR X100 XJ8 XJR X308 Gasket Camshaft Cover A-Bank | E18: 3000 | F18: Normal Used Condition. | H18: =PartsMaster!$Q15 -> Cam Cover Gasket RH A Bank | I18: 9886 | K18: 0 | L18: 0 | M18: =PartsMaster!$D15 -> 0 | O18: GBP | P18: =PartsMaster!$S15/1.45 -> 14.482759 | S18: 30 | T18: 0 | U18: EE | Z18: ="<P>"&PartsMaster!$I15&" "&PartsMaster!$H15&"</P>"&"<P>Jaguar part name "&PartsMaster!$E15&"</P><P>Product numbers "&PartsMaster!R15&" "&DQ18&"</P><P>Fits starting from VIN/ModelYear "&PartsMaster!$F15&" until VIN/ModelYear "&PartsMaster!$G15&"</P><P>Condition: "&PartsMaster!AB15&"</P><P> (part source "&PartsMaster!AD15&")</P><P>Notes: "&PartsMaster!AA15&"</P>" -> <P> Gasket / Seal / O-Ring</P><P>Jaguar part name </P><P>Product numbers AJ88400 AJ88400</P><P>Fits starting from VIN/ModelYear Engine #9810290000 until VIN/ModelYear </P><P>Condition: </P><P> (part source )</P><P>Notes: </P> | AA18: BasicStyle | AC18: 0 | AD18: 0 | AE18: None | AF18: 7 | AG18: 0 | AH18: 0 | AI18: 0 | AJ18: 0 | AK18: 0 | AO18: 0.00 | AR18: 0 | AS18: 10112 | AV18: Tallinn | AX18: 62128510024 | AY18: 62035811024 | AZ18: 55187694024 | BA18: Shipping per agreement | BB18: PayPal:Immediate pay | BC18: Return Policy | BD18: 1 | BE18: 0 | BF18: 0 | BG18: 0 | BN18: Metric | BV18: 0 | CL18: 0 | DD18: 0|287377024| | DE18: 0|287377024| | DI18: 0 | DP18: Jaguar | DQ18: =PartsMaster!$A15 -> AJ88400 | DR18: Yes | DS18: =PartsMaster!$K16&" "&PartsMaster!L16&" "&PartsMaster!$M16
A19: Add | B19: UK | C19: FixedPriceItem | D19: =PartsMaster!B162&" "&PartsMaster!$C162 -> Jaguar XK8 XKR X100 Seatbelt Front - Topmount plastic cover trim | E19: 3000 | F19: Normal Used Condition. | H19: =PartsMaster!$Q162 -> 0 | I19: 9886 | K19: 0 | L19: 0 | M19: =PartsMaster!$D162 -> 0 | O19: GBP | P19: =PartsMaster!$S162/1.45 -> 0 | S19: 30 | T19: 0 | U19: EE | Z19: ="<P>"&PartsMaster!$I162&" "&PartsMaster!$H162&"</P>"&"<P>Jaguar part name "&PartsMaster!$E162&"</P><P>Product numbers "&PartsMaster!R162&" "&DQ19&"</P><P>Fits starting from VIN/ModelYear "&PartsMaster!$F162&" until VIN/ModelYear "&PartsMaster!$G162&"</P><P>Condition: "&PartsMaster!AB162&"</P><P> (part source "&PartsMaster!AD162&")</P><P>Notes: "&PartsMaster!AA162&"</P>" -> <P>Cap / Cover Cap / Cover / Trim</P><P>Jaguar part name Seatbelt Cap</P><P>Product numbers HND7150AALEG </P><P>Fits starting from VIN/ModelYear 19229 until VIN/ModelYear </P><P>Condition: </P><P> (part source )</P><P>Notes: </P> | AA19: BasicStyle | AC19: 0 | AD19: 0 | AE19: None | AF19: 7 | AG19: 0 | AH19: 0 | AI19: 0 | AJ19: 0 | AK19: 0 | AO19: 0.00 | AR19: 0 | AS19: 10112 | AV19: Tallinn | AX19: 62128510024 | AY19: 62035811024 | AZ19: 55187694024 | BA19: Shipping per agreement | BB19: PayPal:Immediate pay | BC19: Return Policy | BD19: 1 | BE19: 0 | BF19: 0 | BG19: 0 | BN19: Metric | BV19: 0 | CL19: 0 | DD19: 0|287377024| | DE19: 0|287377024| | DI19: 0 | DP19: Jaguar | DQ19: =PartsMaster!$A162 -> HND7150AALEG | DR19: Yes | DS19: =PartsMaster!$K163&" "&PartsMaster!L163&" "&PartsMaster!$M163 -> Center Left
A20: Add | B20: UK | C20: FixedPriceItem | D20: =PartsMaster!B47&" "&PartsMaster!$C47 -> Jaguar XK8 XKR X100 GASKET-MANIFOLD DOWNPIPE | E20: 3000 | F20: Normal Used Condition. | H20: =PartsMaster!$Q47 -> GASKET-MANIFOLD DOWNPIPE | I20: 9886 | K20: 0 | L20: 0 | M20: =PartsMaster!$D47 -> 0 | O20: GBP | P20: =PartsMaster!$S47/1.45 -> 0 | S20: 30 | T20: 0 | U20: EE | Z20: ="<P>"&PartsMaster!$I47&" "&PartsMaster!$H47&"</P>"&"<P>Jaguar part name "&PartsMaster!$E47&"</P><P>Product numbers "&PartsMaster!R47&" "&DQ20&"</P><P>Fits starting from VIN/ModelYear "&PartsMaster!$F47&" until VIN/ModelYear "&PartsMaster!$G47&"</P><P>Condition: "&PartsMaster!AB47&"</P><P> (part source "&PartsMaster!AD47&")</P><P>Notes: "&PartsMaster!AA47&"</P>" -> <P>Engine Inlet Gasket / Seal / O-Ring</P><P>Jaguar part name </P><P>Product numbers EAZ2050 EAZ2050</P><P>Fits starting from VIN/ModelYear until VIN/ModelYear </P><P>Condition: British Parts</P><P> (part source )</P><P>Notes: </P> | AA20: BasicStyle | AC20: 0 | AD20: 0 | AE20: None | AF20: 7 | AG20: 0 | AH20: 0 | AI20: 0 | AJ20: 0 | AK20: 0 | AO20: 0.00 | AR20: 0 | AS20: 10112 | AV20: Tallinn | AX20: 62128510024 | AY20: 62035811024 | AZ20: 55187694024 | BA20: Shipping per agreement | BB20: PayPal:Immediate pay | BC20: Return Policy | BD20: 1 | BE20: 0 | BF20: 0 | BG20: 0 | BN20: Metric | BV20: 0 | CL20: 0 | DD20: 0|287377024| | DE20: 0|287377024| | DI20: 0 | DP20: Jaguar | DQ20: =PartsMaster!$A47 -> EAZ2050 | DR20: Yes | DS20: =PartsMaster!$K48&" "&PartsMaster!L48&" "&PartsMaster!$M48
A21: Add | B21: UK | C21: FixedPriceItem | D21: =PartsMaster!B364&" "&PartsMaster!$C364 -> Jaguar XK8 XKR X100 Repaint Steering Wheel Airback cover | E21: 3000 | F21: Normal Used Condition. | H21: =PartsMaster!$Q364 -> 0 | I21: 9886 | K21: 0 | L21: 0 | M21: =PartsMaster!$D364 -> 0 | O21: GBP | P21: =PartsMaster!$S364/1.45 -> 0 | S21: 30 | T21: 0 | U21: EE | Z21: ="<P>"&PartsMaster!$I364&" "&PartsMaster!$H364&"</P>"&"<P>Jaguar part name "&PartsMaster!$E364&"</P><P>Product numbers "&PartsMaster!R364&" "&DQ21&"</P><P>Fits starting from VIN/ModelYear "&PartsMaster!$F364&" until VIN/ModelYear "&PartsMaster!$G364&"</P><P>Condition: "&PartsMaster!AB364&"</P><P> (part source "&PartsMaster!AD364&")</P><P>Notes: "&PartsMaster!AA364&"</P>" -> <P> </P><P>Jaguar part name </P><P>Product numbers 0</P><P>Fits starting from VIN/ModelYear until VIN/ModelYear </P><P>Condition: </P><P> (part source )</P><P>Notes: </P> | AA21: BasicStyle | AC21: 0 | AD21: 0 | AE21: None | AF21: 7 | AG21: 0 | AH21: 0 | AI21: 0 | AJ21: 0 | AK21: 0 | AO21: 0.00 | AR21: 0 | AS21: 10112 | AV21: Tallinn | AX21: 62128510024 | AY21: 62035811024 | AZ21: 55187694024 | BA21: Shipping per agreement | BB21: PayPal:Immediate pay | BC21: Return Policy | BD21: 1 | BE21: 0 | BF21: 0 | BG21: 0 | BN21: Metric | BV21: 0 | CL21: 0 | DD21: 0|287377024| | DE21: 0|287377024| | DI21: 0 | DP21: Jaguar | DQ21: =PartsMaster!$A364 -> 0 | DR21: Yes | DS21: =PartsMaster!$K365&" "&PartsMaster!L365&" "&PartsMaster!$M365
A22: Add | B22: UK | C22: FixedPriceItem | D22: =PartsMaster!B49&" "&PartsMaster!$C49 -> Jaguar XK8 XKR X100 Plenum cover finisher Cap | E22: 3000 | F22: Normal Used Condition. | H22: =PartsMaster!$Q49 -> 0 | I22: 9886 | K22: 0 | L22: 0 | M22: =PartsMaster!$D49 -> 0 | O22: GBP | P22: =PartsMaster!$S49/1.45 -> 0 | S22: 30 | T22: 0 | U22: EE | Z22: ="<P>"&PartsMaster!$I49&" "&PartsMaster!$H49&"</P>"&"<P>Jaguar part name "&PartsMaster!$E49&"</P><P>Product numbers "&PartsMaster!R49&" "&DQ22&"</P><P>Fits starting from VIN/ModelYear "&PartsMaster!$F49&" until VIN/ModelYear "&PartsMaster!$G49&"</P><P>Condition: "&PartsMaster!AB49&"</P><P> (part source "&PartsMaster!AD49&")</P><P>Notes: "&PartsMaster!AA49&"</P>" -> <P>Cap / Cover Cap / Cover / Trim</P><P>Jaguar part name </P><P>Product numbers EU HJA3835AA / HJA3835AA</P><P>Fits starting from VIN/ModelYear until VIN/ModelYear </P><P>Condition: </P><P> (part source )</P><P>Notes: </P> | AA22: BasicStyle | AC22: 0 | AD22: 0 | AE22: None | AF22: 7 | AG22: 0 | AH22: 0 | AI22: 0 | AJ22: 0 | AK22: 0 | AO22: 0.00 | AR22: 0 | AS22: 10112 | AV22: Tallinn | AX22: 62128510024 | AY22: 62035811024 | AZ22: 55187694024 | BA22: Shipping per agreement | BB22: PayPal:Immediate pay | BC22: Return Policy | BD22: 1 | BE22: 0 | BF22: 0 | BG22: 0 | BN22: Metric | BV22: 0 | CL22: 0 | DD22: 0|287377024| | DE22: 0|287377024| | DI22: 0 | DP22: Jaguar | DQ22: =PartsMaster!$A49 -> EU HJA3835AA / HJA3835AA | DR22: Yes | DS22: =PartsMaster!$K50&" "&PartsMaster!L50&" "&PartsMaster!$M50
A23: Add | B23: UK | C23: FixedPriceItem | D23: =PartsMaster!B211&" "&PartsMaster!$C211 -> Jaguar XK8 XKR X100 ABS Sensor | E23: 3000 | F23: Normal Used Condition. | H23: =PartsMaster!$Q211 -> ABS Sensor | I23: 9886 | K23: 0 | L23: 0 | M23: =PartsMaster!$D211 -> 4 | O23: GBP | P23: =PartsMaster!$S211/1.45 -> 51.724138 | S23: 30 | T23: 0 | U23: EE | Z23: ="<P>"&PartsMaster!$I211&" "&PartsMaster!$H211&"</P>"&"<P>Jaguar part name "&PartsMaster!$E211&"</P><P>Product numbers "&PartsMaster!R211&" "&DQ23&"</P><P>Fits starting from VIN/ModelYear "&PartsMaster!$F211&" until VIN/ModelYear "&PartsMaster!$G211&"</P><P>Condition: "&PartsMaster!AB211&"</P><P> (part source "&PartsMaster!AD211&")</P><P>Notes: "&PartsMaster!AA211&"</P>" -> <P>Brakes Sensor</P><P>Jaguar part name Wheel Speed Sensor</P><P>Product numbers LJA2226AA LJA2226AA</P><P>Fits starting from VIN/ModelYear until VIN/ModelYear </P><P>Condition: Extra spare</P><P> (part source JP)</P><P>Notes: </P> | AA23: BasicStyle | AC23: 0 | AD23: 0 | AE23: None | AF23: 7 | AG23: 0 | AH23: 0 | AI23: 0 | AJ23: 0 | AK23: 0 | AO23: 0.00 | AR23: 0 | AS23: 10112 | AV23: Tallinn | AX23: 62128510024 | AY23: 62035811024 | AZ23: 55187694024 | BA23: Shipping per agreement | BB23: PayPal:Immediate pay | BC23: Return Policy | BD23: 1 | BE23: 0 | BF23: 0 | BG23: 0 | BN23: Metric | BV23: 0 | CL23: 0 | DD23: 0|287377024| | DE23: 0|287377024| | DI23: 0 | DP23: Jaguar | DQ23: =PartsMaster!$A211 -> LJA2226AA | DR23: Yes | DS23: =PartsMaster!$K212&" "&PartsMaster!L212&" "&PartsMaster!$M212
A24: Add | B24: UK | C24: FixedPriceItem | D24: =PartsMaster!B191&" "&PartsMaster!$C191 -> Jaguar XK8 XKR X100 Suspension Spring Kit (Road Spring) | E24: 3000 | F24: Normal Used Condition. | H24: =PartsMaster!$Q191 -> KIT-ROAD SPR | I24: 9886 | K24: 0 | L24: 0 | M24: =PartsMaster!$D191 -> 0 | O24: GBP | P24: =PartsMaster!$S191/1.45 -> 0 | S24: 30 | T24: 0 | U24: EE | Z24: ="<P>"&PartsMaster!$I191&" "&PartsMaster!$H191&"</P>"&"<P>Jaguar part name "&PartsMaster!$E191&"</P><P>Product numbers "&PartsMaster!R191&" "&DQ24&"</P><P>Fits starting from VIN/ModelYear "&PartsMaster!$F191&" until VIN/ModelYear "&PartsMaster!$G191&"</P><P>Condition: "&PartsMaster!AB191&"</P><P> (part source "&PartsMaster!AD191&")</P><P>Notes: "&PartsMaster!AA191&"</P>" -> <P>Suspension Spring</P><P>Jaguar part name Front Coil Spring</P><P>Product numbers JLM20712 JLM20712</P><P>Fits starting from VIN/ModelYear 031303 until VIN/ModelYear 042775</P><P>Condition: SNG Barrat UK</P><P> (part source )</P><P>Notes: Convertible</P> | AA24: BasicStyle | AC24: 0 | AD24: 0 | AE24: None | AF24: 7 | AG24: 0 | AH24: 0 | AI24: 0 | AJ24: 0 | AK24: 0 | AO24: 0.00 | AR24: 0 | AS24: 10112 | AV24: Tallinn | AX24: 62128510024 | AY24: 62035811024 | AZ24: 55187694024 | BA24: Shipping per agreement | BB24: PayPal:Immediate pay | BC24: Return Policy | BD24: 1 | BE24: 0 | BF24: 0 | BG24: 0 | BN24: Metric | BV24: 0 | CL24: 0 | DD24: 0|287377024| | DE24: 0|287377024| | DI24: 0 | DP24: Jaguar | DQ24: =PartsMaster!$A191 -> JLM20712 | DR24: Yes | DS24: =PartsMaster!$K192&" "&PartsMaster!L192&" "&PartsMaster!$M192 -> Rear Left/Right
A25: Add | B25: UK | C25: FixedPriceItem | D25: =PartsMaster!B213&" "&PartsMaster!$C213 -> Jaguar XK8 XKR X100 Cigar-lighter element-front | E25: 3000 | F25: Normal Used Condition. | H25: =PartsMaster!$Q213 -> 0 | I25: 9886 | K25: 0 | L25: 0 | M25: =PartsMaster!$D213 -> 0 | O25: GBP | P25: =PartsMaster!$S213/1.45 -> 0 | S25: 30 | T25: 0 | U25: EE | Z25: ="<P>"&PartsMaster!$I213&" "&PartsMaster!$H213&"</P>"&"<P>Jaguar part name "&PartsMaster!$E213&"</P><P>Product numbers "&PartsMaster!R213&" "&DQ25&"</P><P>Fits starting from VIN/ModelYear "&PartsMaster!$F213&" until VIN/ModelYear "&PartsMaster!$G213&"</P><P>Condition: "&PartsMaster!AB213&"</P><P> (part source "&PartsMaster!AD213&")</P><P>Notes: "&PartsMaster!AA213&"</P>" -> <P>Cigar Lighter </P><P>Jaguar part name Cigar-lighter element-front</P><P>Product numbers LJA2730AA</P><P>Fits starting from VIN/ModelYear until VIN/ModelYear </P><P>Condition: </P><P> (part source )</P><P>Notes: </P> | AA25: BasicStyle | AC25: 0 | AD25: 0 | AE25: None | AF25: 7 | AG25: 0 | AH25: 0 | AI25: 0 | AJ25: 0 | AK25: 0 | AO25: 0.00 | AR25: 0 | AS25: 10112 | AV25: Tallinn | AX25: 62128510024 | AY25: 62035811024 | AZ25: 55187694024 | BA25: Shipping per agreement | BB25: PayPal:Immediate pay | BC25: Return Policy | BD25: 1 | BE25: 0 | BF25: 0 | BG25: 0 | BN25: Metric | BV25: 0 | CL25: 0 | DD25: 0|287377024| | DE25: 0|287377024| | DI25: 0 | DP25: Jaguar | DQ25: =PartsMaster!$A213 -> LJA2730AA | DR25: Yes | DS25: =PartsMaster!$K214&" "&PartsMaster!L214&" "&PartsMaster!$M214 -> Front Right
A26: Add | B26: UK | C26: FixedPriceItem | D26: =PartsMaster!B22&" "&PartsMaster!$C22 -> Jaguar XK8 XKR X100 Seat - Mount Washer | E26: 3000 | F26: Normal Used Condition. | H26: =PartsMaster!$Q22 -> WASHER | I26: 9886 | K26: 0 | L26: 0 | M26: =PartsMaster!$D22 -> 0 | O26: GBP | P26: =PartsMaster!$S22/1.45 -> 0 | S26: 30 | T26: 0 | U26: EE | Z26: ="<P>"&PartsMaster!$I22&" "&PartsMaster!$H22&"</P>"&"<P>Jaguar part name "&PartsMaster!$E22&"</P><P>Product numbers "&PartsMaster!R22&" "&DQ26&"</P><P>Fits starting from VIN/ModelYear "&PartsMaster!$F22&" until VIN/ModelYear "&PartsMaster!$G22&"</P><P>Condition: "&PartsMaster!AB22&"</P><P> (part source "&PartsMaster!AD22&")</P><P>Notes: "&PartsMaster!AA22&"</P>" -> <P>Mounting Washer</P><P>Jaguar part name </P><P>Product numbers C21069 C21069</P><P>Fits starting from VIN/ModelYear until VIN/ModelYear </P><P>Condition: SNG Barrat</P><P> (part source )</P><P>Notes: </P> | AA26: BasicStyle | AC26: 0 | AD26: 0 | AE26: None | AF26: 7 | AG26: 0 | AH26: 0 | AI26: 0 | AJ26: 0 | AK26: 0 | AO26: 0.00 | AR26: 0 | AS26: 10112 | AV26: Tallinn | AX26: 62128510024 | AY26: 62035811024 | AZ26: 55187694024 | BA26: Shipping per agreement | BB26: PayPal:Immediate pay | BC26: Return Policy | BD26: 1 | BE26: 0 | BF26: 0 | BG26: 0 | BN26: Metric | BV26: 0 | CL26: 0 | DD26: 0|287377024| | DE26: 0|287377024| | DI26: 0 | DP26: Jaguar | DQ26: =PartsMaster!$A22 -> C21069 | DR26: Yes | DS26: =PartsMaster!$K23&" "&PartsMaster!L23&" "&PartsMaster!$M23
A27: Add | B27: UK | C27: FixedPriceItem | D27: =PartsMaster!B375&" "&PartsMaster!$C375 -> Jaguar XK8 XKR X100 Seat - Mechanism cover - Coffee | E27: 3000 | F27: Normal Used Condition. | H27: =PartsMaster!$Q375 -> 0 | I27: 9886 | K27: 0 | L27: 0 | M27: =PartsMaster!$D375 -> 0 | O27: GBP | P27: =PartsMaster!$S375/1.45 -> 0 | S27: 30 | T27: 0 | U27: EE | Z27: ="<P>"&PartsMaster!$I375&" "&PartsMaster!$H375&"</P>"&"<P>Jaguar part name "&PartsMaster!$E375&"</P><P>Product numbers "&PartsMaster!R375&" "&DQ27&"</P><P>Fits starting from VIN/ModelYear "&PartsMaster!$F375&" until VIN/ModelYear "&PartsMaster!$G375&"</P><P>Condition: "&PartsMaster!AB375&"</P><P> (part source "&PartsMaster!AD375&")</P><P>Notes: "&PartsMaster!AA375&"</P>" -> <P>Cap / Cover Cap / Cover / Trim</P><P>Jaguar part name </P><P>Product numbers 0</P><P>Fits starting from VIN/ModelYear 0 until VIN/ModelYear 18107</P><P>Condition: </P><P> (part source )</P><P>Notes: </P> | AA27: BasicStyle | AC27: 0 | AD27: 0 | AE27: None | AF27: 7 | AG27: 0 | AH27: 0 | AI27: 0 | AJ27: 0 | AK27: 0 | AO27: 0.00 | AR27: 0 | AS27: 10112 | AV27: Tallinn | AX27: 62128510024 | AY27: 62035811024 | AZ27: 55187694024 | BA27: Shipping per agreement | BB27: PayPal:Immediate pay | BC27: Return Policy | BD27: 1 | BE27: 0 | BF27: 0 | BG27: 0 | BN27: Metric | BV27: 0 | CL27: 0 | DD27: 0|287377024| | DE27: 0|287377024| | DI27: 0 | DP27: Jaguar | DQ27: =PartsMaster!$A375 -> 0 | DR27: Yes | DS27: =PartsMaster!$K376&" "&PartsMaster!L376&" "&PartsMaster!$M376 -> Front Right Low
A28: Add | B28: UK | C28: FixedPriceItem | D28: =PartsMaster!B289&" "&PartsMaster!$C289 -> Jaguar XK8 XKR X100 XJ8 XJR X308 Timing Chain Guide Rail | E28: 3000 | F28: Normal Used Condition. | H28: =PartsMaster!$Q289 -> TIMING CHAIN GUIDE | I28: 9886 | K28: 0 | L28: 0 | M28: =PartsMaster!$D289 -> 0 | O28: GBP | P28: =PartsMaster!$S289/1.45 -> 0 | S28: 30 | T28: 0 | U28: EE | Z28: ="<P>"&PartsMaster!$I289&" "&PartsMaster!$H289&"</P>"&"<P>Jaguar part name "&PartsMaster!$E289&"</P><P>Product numbers "&PartsMaster!R289&" "&DQ28&"</P><P>Fits starting from VIN/ModelYear "&PartsMaster!$F289&" until VIN/ModelYear "&PartsMaster!$G289&"</P><P>Condition: "&PartsMaster!AB289&"</P><P> (part source "&PartsMaster!AD289&")</P><P>Notes: "&PartsMaster!AA289&"</P>" -> <P>Engine Timing Chain guide / Blade</P><P>Jaguar part name </P><P>Product numbers NCA1998AB NCA1998AB</P><P>Fits starting from VIN/ModelYear X100, 1996 - X308, 1998 until VIN/ModelYear X100-X308 Engine #0108122359</P><P>Condition: British Parts</P><P> (part source )</P><P>Notes: </P> | AA28: BasicStyle | AC28: 0 | AD28: 0 | AE28: None | AF28: 7 | AG28: 0 | AH28: 0 | AI28: 0 | AJ28: 0 | AK28: 0 | AO28: 0.00 | AR28: 0 | AS28: 10112 | AV28: Tallinn | AX28: 62128510024 | AY28: 62035811024 | AZ28: 55187694024 | BA28: Shipping per agreement | BB28: PayPal:Immediate pay | BC28: Return Policy | BD28: 1 | BE28: 0 | BF28: 0 | BG28: 0 | BN28: Metric | BV28: 0 | CL28: 0 | DD28: 0|287377024| | DE28: 0|287377024| | DI28: 0 | DP28: Jaguar | DQ28: =PartsMaster!$A289 -> NCA1998AB | DR28: Yes | DS28: =PartsMaster!$K290&" "&PartsMaster!L290&" "&PartsMaster!$M290
A29: Add | B29: UK | C29: FixedPriceItem | D29: =PartsMaster!B19&" "&PartsMaster!$C19 -> Jaguar XK8 XKR X100 CYLINDER HEAD BOLT | E29: 3000 | F29: Normal Used Condition. | H29: =PartsMaster!$Q19 -> CYLINDER HEAD BOLT | I29: 9886 | K29: 0 | L29: 0 | M29: =PartsMaster!$D19 -> 0 | O29: GBP | P29: =PartsMaster!$S19/1.45 -> 0 | S29: 30 | T29: 0 | U29: EE | Z29: ="<P>"&PartsMaster!$I19&" "&PartsMaster!$H19&"</P>"&"<P>Jaguar part name "&PartsMaster!$E19&"</P><P>Product numbers "&PartsMaster!R19&" "&DQ29&"</P><P>Fits starting from VIN/ModelYear "&PartsMaster!$F19&" until VIN/ModelYear "&PartsMaster!$G19&"</P><P>Condition: "&PartsMaster!AB19&"</P><P> (part source "&PartsMaster!AD19&")</P><P>Notes: "&PartsMaster!AA19&"</P>" -> <P>Engine Bolt / Screw</P><P>Jaguar part name </P><P>Product numbers AJ89986 AJ89986</P><P>Fits starting from VIN/ModelYear until VIN/ModelYear </P><P>Condition: British Parts</P><P> (part source )</P><P>Notes: </P> | AA29: BasicStyle | AC29: 0 | AD29: 0 | AE29: None | AF29: 7 | AG29: 0 | AH29: 0 | AI29: 0 | AJ29: 0 | AK29: 0 | AO29: 0.00 | AR29: 0 | AS29: 10112 | AV29: Tallinn | AX29: 62128510024 | AY29: 62035811024 | AZ29: 55187694024 | BA29: Shipping per agreement | BB29: PayPal:Immediate pay | BC29: Return Policy | BD29: 1 | BE29: 0 | BF29: 0 | BG29: 0 | BN29: Metric | BV29: 0 | CL29: 0 | DD29: 0|287377024| | DE29: 0|287377024| | DI29: 0 | DP29: Jaguar | DQ29: =PartsMaster!$A19 -> AJ89986 | DR29: Yes | DS29: =PartsMaster!$K20&" "&PartsMaster!L20&" "&PartsMaster!$M20 -> Front Left/Right Top(?)
