Workbook

Sheet Trafi parsed
A1: jarnro | B1: VIN | C1: VINClass | D1: VINRange6 | E1: Käyttöönotto | F1: KOVuosi | G1: Mallimerkintä | H1: tyyppihyvaksyntanro | I1: Omamassa | J1: XK/XK8 | K1: XKR | L1: Coupe | M1: Convertible | N1: Unknown | O1: BodyType
A2: ='Ajoneuvorekisteri-Parse Modern '!AO33 -> 1035687 | B2: ='Ajoneuvorekisteri-Parse Modern '!AN33 -> SAJJGAED4A | C2: {=_xlfn.LET(_xlpm.v,UPPER(SUBSTITUTE(CLEAN(TRIM(B2)),CHAR(160),"")),_xlpm.mkt,MID(_xlpm.v,4,1),_xlpm.trans,MID(_xlpm.v,5,1),_xlpm.body,MID(_xlpm.v,6,2),_xlpm.emis,MID(_xlpm.v,8,1),_xlpm.my,MID(_xlpm.v,10,1),_xlfn.IFS(AND(LEN(_xlpm.v)=10,LEFT(_xlpm.v,5)="SAJJG",OR(MID(_xlpm.v,7,1)="E",MID(_xlpm.v,7,1)="F"),OR(_xlpm.emis="D",_xlpm.emis="F"),OR(MID(_xlpm.v,9,1)="3",MID(_xlpm.v,9,1)="4"),_xlpm.my="A"),"X100_EARLY_NORMAL_AR (JDHT)",AND(LEN(_xlpm.v)=10,LEFT(_xlpm.v,5)="SAJJG",MID(_xlpm.v,6,1)="A",OR(MID(_xlpm.v,7,1)="E",MID(_xlpm.v,7,1)="F"),_xlpm.emis="D",OR(MID(_xlpm.v,9,1)="3",MID(_xlpm.v,9,1)="4"),OR(_xlpm.my="V",_xlpm.my="W",_xlpm.my="X")),"X100_NORMAL (JDHT)",AND(LEN(_xlpm.v)=10,LEFT(_xlpm.v,5)="SAJJG",OR(MID(_xlpm.v,6,1)="A",MID(_xlpm.v,6,1)="K",MID(_xlpm.v,6,1)="N",MID(_xlpm.v,6,1)="X"),OR(MID(_xlpm.v,7,1)="E",MID(_xlpm.v,7,1)="F"),OR(_xlpm.emis="D",_xlpm.emis="F"),OR(MID(_xlpm.v,9,1)="3",MID(_xlpm.v,9,1)="4"),OR(_xlpm.my="V",_xlpm.my="W",_xlpm.my="X")),"X100_JLM20300",AND(LEN(_xlpm.v)=10,LEFT(_xlpm.v,5)="SAJJG",OR(MID(_xlpm.v,6,1)="N",MID(_xlpm.v,6,1)="S",MID(_xlpm.v,6,1)="X"),OR(MID(_xlpm.v,7,1)="E",MID(_xlpm.v,7,1)="F"),OR(_xlpm.emis="D",_xlpm.emis="F"),OR(MID(_xlpm.v,9,1)="3",MID(_xlpm.v,9,1)="4"),OR(MID(_xlpm.v,10,1)="V",MID(_xlpm.v,10,1)="W",MID(_xlpm.v,10,1)="X")),"X100_JLM20301",AND(LEN(_xlpm.v)=10,LEFT(_xlpm.v,5)="SAJGX",OR(MID(_xlpm.v,6,1)="2",MID(_xlpm.v,6,1)="5"),OR(MID(_xlpm.v,7,1)="1",MID(_xlpm.v,7,1)="2",MID(_xlpm.v,7,1)="7"),MID(_xlpm.v,8,1)="4",OR(MID(_xlpm.v,10,1)="V",MID(_xlpm.v,10,1)="W",MID(_xlpm.v,10,1)="X")),"X100_AMERICAS_UNIQUE (JLM20301_unique)",AND(LEN(_xlpm.v)=10,LEFT(_xlpm.v,3)="SAJ",OR(_xlpm.mkt="A",_xlpm.mkt="B",_xlpm.mkt="F",_xlpm.mkt="G",_xlpm.mkt="X",_xlpm.mkt="P",_xlpm.mkt="R",_xlpm.mkt="T",_xlpm.mkt="Y",_xlpm.mkt="D",_xlpm.mkt="E",_xlpm.mkt="J",_xlpm.mkt="W"),OR(_xlpm.trans="A",_xlpm.trans="B"),OR(_xlpm.body="41",_xlpm.body="42"),IFERROR(AND(CODE(_xlpm.emis)>=65,CODE(_xlpm.emis)<=88),FALSE),OR(_xlpm.my="X",_xlpm.my="Y",_xlpm.my="1",_xlpm.my="2",_xlpm.my="3",_xlpm.my="4",_xlpm.my="5",_xlpm.my="6",_xlpm.my="7",_xlpm.my="8",_xlpm.my="9")),"XK8-XKR_"&IF(_xlpm.body="41","COUPE_","CONVERTIBLE_")&IF(ISNUMBER(FIND(_xlpm.mkt,"DEJW")),"USA",IF(ISNUMBER(FIND(_xlpm.mkt,"BFGX")),"CANADA","MEXICO"))&IF(_xlpm.trans="A","_AUTO_LHD","_MANUAL_LHD")&"_EMISSION_"&_xlpm.emis&IF(_xlpm.my="X","_1999",IF(_xlpm.my="Y","_2000","_200"&_xlpm.my))&"MY",AND(LEN(_xlpm.v)=10,LEFT(_xlpm.v,3)="SAJ",OR(_xlpm.mkt="A",_xlpm.mkt="B",_xlpm.mkt="D",_xlpm.mkt="E",_xlpm.mkt="F",_xlpm.mkt="J",_xlpm.mkt="K",_xlpm.mkt="P",_xlpm.mkt="R",_xlpm.mkt="W",_xlpm.mkt="X",_xlpm.mkt="Y"),OR(_xlpm.trans="A",_xlpm.trans="C"),OR(_xlpm.body="43",_xlpm.body="4D",_xlpm.body="44",_xlpm.body="4E",_xlpm.body="45",_xlpm.body="46",_xlpm.body="47",_xlpm.body="4F",_xlpm.body="4G"),OR(_xlpm.emis="A",_xlpm.emis="B",_xlpm.emis="C",_xlpm.emis="D",_xlpm.emis="E",_xlpm.emis="F",_xlpm.emis="G",_xlpm.emis="K",_xlpm.emis="N",_xlpm.emis="P",_xlpm.emis="R",_xlpm.emis="S",_xlpm.emis="T",_xlpm.emis="U",_xlpm.emis="V",_xlpm.emis="W",_xlpm.emis="X",_xlpm.emis="Y",_xlpm.emis="1",_xlpm.emis="2",_xlpm.emis="3",_xlpm.emis="4"),OR(_xlpm.my="7",_xlpm.my="8",_xlpm.my="9",_xlpm.my="A",_xlpm.my="B",_xlpm.my="C",_xlpm.my="D",_xlpm.my="E")),"X150_"&IF(_xlpm.my="7","2007MY",IF(_xlpm.my="8","2008MY",IF(_xlpm.my="9","2009MY",IF(_xlpm.my="A","2010MY",IF(_xlpm.my="B","2011MY",IF(_xlpm.my="C","2012MY",IF(_xlpm.my="D","2013MY",IF(_xlpm.my="E","2014MY","UNKNOWN_MY"))))))))&"_MARKET_"&_xlpm.mkt&"_TRANS_"&_xlpm.trans&"_BODY_"&_xlpm.body&"_EMISSION_"&_xlpm.emis&"_CHECK_"&MID(_xlpm.v,9,1),TRUE,IF(LEN(_xlpm.v)<>10,"UNKNOWN: [length="&LEN(_xlpm.v)&"]",IF(LEFT(_xlpm.v,3)<>"SAJ","UNKNOWN: [prefix="&LEFT(_xlpm.v,3)&"]",IF(LEFT(_xlpm.v,5)="SAJJG",IF(NOT(OR(MID(_xlpm.v,7,1)="E",MID(_xlpm.v,7,1)="F")),"UNKNOWN: [7="&MID(_xlpm.v,7,1)&"]",IF(NOT(OR(_xlpm.emis="D",_xlpm.emis="F")),"UNKNOWN: [8="&_xlpm.emis&"]",IF(NOT(OR(MID(_xlpm.v,9,1)="3",MID(_xlpm.v,9,1)="4")),"UNKNOWN: [9="&MID(_xlpm.v,9,1)&"]",IF(NOT(OR(_xlpm.my="A",_xlpm.my="V",_xlpm.my="W",_xlpm.my="X")),"UNKNOWN: [10="&_xlpm.my&"]","UNKNOWN")))),IF(LEFT(_xlpm.v,5)="SAJGX",IF(NOT(OR(MID(_xlpm.v,6,1)="2",MID(_xlpm.v,6,1)="5")),"UNKNOWN: [6="&MID(_xlpm.v,6,1)&"]",IF(NOT(OR(MID(_xlpm.v,7,1)="1",MID(_xlpm.v,7,1)="2",MID(_xlpm.v,7,1)="7")),"UNKNOWN: [7="&MID(_xlpm.v,7,1)&"]",IF(MID(_xlpm.v,8,1)<>"4","UNKNOWN: [8="&MID(_xlpm.v,8,1)&"]",IF(NOT(OR(_xlpm.my="V",_xlpm.my="W",_xlpm.my="X")),"UNKNOWN: [10="&_xlpm.my&"]","UNKNOWN")))),IF(NOT(OR(_xlpm.mkt="A",_xlpm.mkt="B",_xlpm.mkt="F",_xlpm.mkt="G",_xlpm.mkt="X",_xlpm.mkt="P",_xlpm.mkt="R",_xlpm.mkt="T",_xlpm.mkt="Y",_xlpm.mkt="D",_xlpm.mkt="E",_xlpm.mkt="J",_xlpm.mkt="W",_xlpm.mkt="K")),"UNKNOWN: [4="&_xlpm.mkt&"]",IF(NOT(OR(_xlpm.trans="A",_xlpm.trans="B",_xlpm.trans="C")),"UNKNOWN: [5="&_xlpm.trans&"]",IF(NOT(OR(_xlpm.body="41",_xlpm.body="42",_xlpm.body="43",_xlpm.body="4D",_xlpm.body="44",_xlpm.body="45",_xlpm.body="46",_xlpm.body="47",_xlpm.body="4F")),"UNKNOWN: [6-7="&_xlpm.body&"]",IF(NOT(ISNUMBER(SEARCH(_xlpm.emis,"ABCDEFGKNPRSTUVWXY1234"))),"UNKNOWN: [8="&_xlpm.emis&"]",IF(NOT(OR(_xlpm.my="X",_xlpm.my="Y",_xlpm.my="1",_xlpm.my="2",_xlpm.my="3",_xlpm.my="4",_xlpm.my="5",_xlpm.my="6",_xlpm.my="7",_xlpm.my="8",_xlpm.my="9",_xlpm.my="A",_xlpm.my="B",_xlpm.my="C",_xlpm.my="D",_xlpm.my="E")),"UNKNOWN: [10="&_xlpm.my&"]","UNKNOWN")))))))))))} -> X100_EARLY_NORMAL_AR (JDHT) | D2: {=_xlfn.LET(_xlpm.vin,SUBSTITUTE(CLEAN(TRIM(B2)),CHAR(160),""),_xlpm.rawDate,LEFT(TRIM(E2)&"",8),_xlpm.useDate,IF(RIGHT(_xlpm.rawDate,4)="0000",LEFT(_xlpm.rawDate,4)&"1231",_xlpm.rawDate),_xlpm.bodyCode,MID(_xlpm.vin,6,2),_xlpm.yearCode,MID(_xlpm.vin,10,1),IF(OR(LEN(_xlpm.vin)<>10,LEN(_xlpm.rawDate)<>8),"UNKNOWN",IF(OR(_xlpm.bodyCode="43",_xlpm.bodyCode="4D",_xlpm.bodyCode="44",_xlpm.bodyCode="4E",_xlpm.bodyCode="45",_xlpm.bodyCode="4F",_xlpm.bodyCode="46",_xlpm.bodyCode="4G",_xlpm.bodyCode="47"),_xlfn.SWITCH(_xlpm.yearCode,"6","B00379–B06783","7","B06784–B20074","8","B20075–B27986","9","B27987–B32752","A","B32753–B38853","B","B38854–B44939","C","B44940–B48619","D","B48620–B54164","E","B54165–B56794","F","B56795+","UNKNOWN"),IF(_xlpm.useDate<"19960601","001001–001245",IF(_xlpm.useDate<"19970101","001246–008106",IF(_xlpm.useDate<"19970801","008107–018107",IF(_xlpm.useDate<"19980101","018108–023017",IF(_xlpm.useDate<"19980201","023018–024686",IF(_xlpm.useDate<"19980801","024687–031302",IF(_xlpm.useDate<"19990801","031303–036193",IF(_xlpm.useDate<"20010101","036194–042775",IF(OR(_xlpm.bodyCode="41",_xlpm.bodyCode="42"),_xlfn.SWITCH(_xlpm.yearCode,"Y","A00001–A11050","1","A11051–A22928","2","A22929–A30644","3","A30645–A36873","4","A36874–A42347","5","A42348–A48684","UNKNOWN"),"UNKNOWN"))))))))))))} -> 001246–008106 | E2: ='Ajoneuvorekisteri-Parse Modern '!G33 -> 19961018 | F2: =LEFT(Table34[[#This Row],[Käyttöönotto]],4) -> 1996 | G2: ='Ajoneuvorekisteri-Parse Modern '!AA33 -> COUPE XK8 4.0-AUTOMATIC-JGED/259 | H2: =Ajoneuvorekisteri_Parse_Modern_XK_Range_TieliikenneAvoinData_30_06_2026_csv[[#This Row],[tyyppihyvaksyntanro]] -> e11*95/54*0061*00 | I2: ='Ajoneuvorekisteri-Parse Modern '!M33 -> 1720 | J2: =IF(AND( OR( ISNUMBER(SEARCH("XK ", G2)), ISNUMBER(SEARCH("XK8", G2)) ), F2 > 2005 ), 1, 0) -> 1 | K2: =IF(OR( ISNUMBER(SEARCH("XKR", G2)), ), 1, 0) -> 0 | L2: =IF(OR( ISNUMBER(SEARCH("COUPE", G2)), ISNUMBER(SEARCH("COUPÉ", G2)), ISNUMBER(SEARCH("COUP�", G2)) ), 1, 0) -> 1 | M2: =IF(OR( ISNUMBER(SEARCH("CONVERTIBLE",G2)), ISNUMBER(SEARCH("AVOAUTO",G2)), ISNUMBER(SEARCH("AVO",G2)), ISNUMBER(SEARCH("CABRIO",G2)) ),1,0) -> 0 | N2: =IF(AND(Table34[[#This Row],[Coupe]]<>1, Table34[[#This Row],[Convertible]]<>1), 1, 0) -> 0 | O2: =IF(L2=1, "Coupe", IF(M2=1, "Convertible", "Unknown")) -> Coupe
A3: ='Ajoneuvorekisteri-Parse Modern '!AO149 -> 2695845 | B3: ='Ajoneuvorekisteri-Parse Modern '!AN149 -> SAJGX2740V | C3: {=_xlfn.LET(_xlpm.v,UPPER(SUBSTITUTE(CLEAN(TRIM(B3)),CHAR(160),"")),_xlpm.mkt,MID(_xlpm.v,4,1),_xlpm.trans,MID(_xlpm.v,5,1),_xlpm.body,MID(_xlpm.v,6,2),_xlpm.emis,MID(_xlpm.v,8,1),_xlpm.my,MID(_xlpm.v,10,1),_xlfn.IFS(AND(LEN(_xlpm.v)=10,LEFT(_xlpm.v,5)="SAJJG",OR(MID(_xlpm.v,7,1)="E",MID(_xlpm.v,7,1)="F"),OR(_xlpm.emis="D",_xlpm.emis="F"),OR(MID(_xlpm.v,9,1)="3",MID(_xlpm.v,9,1)="4"),_xlpm.my="A"),"X100_EARLY_NORMAL_AR (JDHT)",AND(LEN(_xlpm.v)=10,LEFT(_xlpm.v,5)="SAJJG",MID(_xlpm.v,6,1)="A",OR(MID(_xlpm.v,7,1)="E",MID(_xlpm.v,7,1)="F"),_xlpm.emis="D",OR(MID(_xlpm.v,9,1)="3",MID(_xlpm.v,9,1)="4"),OR(_xlpm.my="V",_xlpm.my="W",_xlpm.my="X")),"X100_NORMAL (JDHT)",AND(LEN(_xlpm.v)=10,LEFT(_xlpm.v,5)="SAJJG",OR(MID(_xlpm.v,6,1)="A",MID(_xlpm.v,6,1)="K",MID(_xlpm.v,6,1)="N",MID(_xlpm.v,6,1)="X"),OR(MID(_xlpm.v,7,1)="E",MID(_xlpm.v,7,1)="F"),OR(_xlpm.emis="D",_xlpm.emis="F"),OR(MID(_xlpm.v,9,1)="3",MID(_xlpm.v,9,1)="4"),OR(_xlpm.my="V",_xlpm.my="W",_xlpm.my="X")),"X100_JLM20300",AND(LEN(_xlpm.v)=10,LEFT(_xlpm.v,5)="SAJJG",OR(MID(_xlpm.v,6,1)="N",MID(_xlpm.v,6,1)="S",MID(_xlpm.v,6,1)="X"),OR(MID(_xlpm.v,7,1)="E",MID(_xlpm.v,7,1)="F"),OR(_xlpm.emis="D",_xlpm.emis="F"),OR(MID(_xlpm.v,9,1)="3",MID(_xlpm.v,9,1)="4"),OR(MID(_xlpm.v,10,1)="V",MID(_xlpm.v,10,1)="W",MID(_xlpm.v,10,1)="X")),"X100_JLM20301",AND(LEN(_xlpm.v)=10,LEFT(_xlpm.v,5)="SAJGX",OR(MID(_xlpm.v,6,1)="2",MID(_xlpm.v,6,1)="5"),OR(MID(_xlpm.v,7,1)="1",MID(_xlpm.v,7,1)="2",MID(_xlpm.v,7,1)="7"),MID(_xlpm.v,8,1)="4",OR(MID(_xlpm.v,10,1)="V",MID(_xlpm.v,10,1)="W",MID(_xlpm.v,10,1)="X")),"X100_AMERICAS_UNIQUE (JLM20301_unique)",AND(LEN(_xlpm.v)=10,LEFT(_xlpm.v,3)="SAJ",OR(_xlpm.mkt="A",_xlpm.mkt="B",_xlpm.mkt="F",_xlpm.mkt="G",_xlpm.mkt="X",_xlpm.mkt="P",_xlpm.mkt="R",_xlpm.mkt="T",_xlpm.mkt="Y",_xlpm.mkt="D",_xlpm.mkt="E",_xlpm.mkt="J",_xlpm.mkt="W"),OR(_xlpm.trans="A",_xlpm.trans="B"),OR(_xlpm.body="41",_xlpm.body="42"),IFERROR(AND(CODE(_xlpm.emis)>=65,CODE(_xlpm.emis)<=88),FALSE),OR(_xlpm.my="X",_xlpm.my="Y",_xlpm.my="1",_xlpm.my="2",_xlpm.my="3",_xlpm.my="4",_xlpm.my="5",_xlpm.my="6",_xlpm.my="7",_xlpm.my="8",_xlpm.my="9")),"XK8-XKR_"&IF(_xlpm.body="41","COUPE_","CONVERTIBLE_")&IF(ISNUMBER(FIND(_xlpm.mkt,"DEJW")),"USA",IF(ISNUMBER(FIND(_xlpm.mkt,"BFGX")),"CANADA","MEXICO"))&IF(_xlpm.trans="A","_AUTO_LHD","_MANUAL_LHD")&"_EMISSION_"&_xlpm.emis&IF(_xlpm.my="X","_1999",IF(_xlpm.my="Y","_2000","_200"&_xlpm.my))&"MY",AND(LEN(_xlpm.v)=10,LEFT(_xlpm.v,3)="SAJ",OR(_xlpm.mkt="A",_xlpm.mkt="B",_xlpm.mkt="D",_xlpm.mkt="E",_xlpm.mkt="F",_xlpm.mkt="J",_xlpm.mkt="K",_xlpm.mkt="P",_xlpm.mkt="R",_xlpm.mkt="W",_xlpm.mkt="X",_xlpm.mkt="Y"),OR(_xlpm.trans="A",_xlpm.trans="C"),OR(_xlpm.body="43",_xlpm.body="4D",_xlpm.body="44",_xlpm.body="4E",_xlpm.body="45",_xlpm.body="46",_xlpm.body="47",_xlpm.body="4F",_xlpm.body="4G"),OR(_xlpm.emis="A",_xlpm.emis="B",_xlpm.emis="C",_xlpm.emis="D",_xlpm.emis="E",_xlpm.emis="F",_xlpm.emis="G",_xlpm.emis="K",_xlpm.emis="N",_xlpm.emis="P",_xlpm.emis="R",_xlpm.emis="S",_xlpm.emis="T",_xlpm.emis="U",_xlpm.emis="V",_xlpm.emis="W",_xlpm.emis="X",_xlpm.emis="Y",_xlpm.emis="1",_xlpm.emis="2",_xlpm.emis="3",_xlpm.emis="4"),OR(_xlpm.my="7",_xlpm.my="8",_xlpm.my="9",_xlpm.my="A",_xlpm.my="B",_xlpm.my="C",_xlpm.my="D",_xlpm.my="E")),"X150_"&IF(_xlpm.my="7","2007MY",IF(_xlpm.my="8","2008MY",IF(_xlpm.my="9","2009MY",IF(_xlpm.my="A","2010MY",IF(_xlpm.my="B","2011MY",IF(_xlpm.my="C","2012MY",IF(_xlpm.my="D","2013MY",IF(_xlpm.my="E","2014MY","UNKNOWN_MY"))))))))&"_MARKET_"&_xlpm.mkt&"_TRANS_"&_xlpm.trans&"_BODY_"&_xlpm.body&"_EMISSION_"&_xlpm.emis&"_CHECK_"&MID(_xlpm.v,9,1),TRUE,IF(LEN(_xlpm.v)<>10,"UNKNOWN: [length="&LEN(_xlpm.v)&"]",IF(LEFT(_xlpm.v,3)<>"SAJ","UNKNOWN: [prefix="&LEFT(_xlpm.v,3)&"]",IF(LEFT(_xlpm.v,5)="SAJJG",IF(NOT(OR(MID(_xlpm.v,7,1)="E",MID(_xlpm.v,7,1)="F")),"UNKNOWN: [7="&MID(_xlpm.v,7,1)&"]",IF(NOT(OR(_xlpm.emis="D",_xlpm.emis="F")),"UNKNOWN: [8="&_xlpm.emis&"]",IF(NOT(OR(MID(_xlpm.v,9,1)="3",MID(_xlpm.v,9,1)="4")),"UNKNOWN: [9="&MID(_xlpm.v,9,1)&"]",IF(NOT(OR(_xlpm.my="A",_xlpm.my="V",_xlpm.my="W",_xlpm.my="X")),"UNKNOWN: [10="&_xlpm.my&"]","UNKNOWN")))),IF(LEFT(_xlpm.v,5)="SAJGX",IF(NOT(OR(MID(_xlpm.v,6,1)="2",MID(_xlpm.v,6,1)="5")),"UNKNOWN: [6="&MID(_xlpm.v,6,1)&"]",IF(NOT(OR(MID(_xlpm.v,7,1)="1",MID(_xlpm.v,7,1)="2",MID(_xlpm.v,7,1)="7")),"UNKNOWN: [7="&MID(_xlpm.v,7,1)&"]",IF(MID(_xlpm.v,8,1)<>"4","UNKNOWN: [8="&MID(_xlpm.v,8,1)&"]",IF(NOT(OR(_xlpm.my="V",_xlpm.my="W",_xlpm.my="X")),"UNKNOWN: [10="&_xlpm.my&"]","UNKNOWN")))),IF(NOT(OR(_xlpm.mkt="A",_xlpm.mkt="B",_xlpm.mkt="F",_xlpm.mkt="G",_xlpm.mkt="X",_xlpm.mkt="P",_xlpm.mkt="R",_xlpm.mkt="T",_xlpm.mkt="Y",_xlpm.mkt="D",_xlpm.mkt="E",_xlpm.mkt="J",_xlpm.mkt="W",_xlpm.mkt="K")),"UNKNOWN: [4="&_xlpm.mkt&"]",IF(NOT(OR(_xlpm.trans="A",_xlpm.trans="B",_xlpm.trans="C")),"UNKNOWN: [5="&_xlpm.trans&"]",IF(NOT(OR(_xlpm.body="41",_xlpm.body="42",_xlpm.body="43",_xlpm.body="4D",_xlpm.body="44",_xlpm.body="45",_xlpm.body="46",_xlpm.body="47",_xlpm.body="4F")),"UNKNOWN: [6-7="&_xlpm.body&"]",IF(NOT(ISNUMBER(SEARCH(_xlpm.emis,"ABCDEFGKNPRSTUVWXY1234"))),"UNKNOWN: [8="&_xlpm.emis&"]",IF(NOT(OR(_xlpm.my="X",_xlpm.my="Y",_xlpm.my="1",_xlpm.my="2",_xlpm.my="3",_xlpm.my="4",_xlpm.my="5",_xlpm.my="6",_xlpm.my="7",_xlpm.my="8",_xlpm.my="9",_xlpm.my="A",_xlpm.my="B",_xlpm.my="C",_xlpm.my="D",_xlpm.my="E")),"UNKNOWN: [10="&_xlpm.my&"]","UNKNOWN")))))))))))} -> X100_AMERICAS_UNIQUE (JLM20301_unique) | D3: {=_xlfn.LET(_xlpm.vin,SUBSTITUTE(CLEAN(TRIM(B3)),CHAR(160),""),_xlpm.rawDate,LEFT(TRIM(E3)&"",8),_xlpm.useDate,IF(RIGHT(_xlpm.rawDate,4)="0000",LEFT(_xlpm.rawDate,4)&"1231",_xlpm.rawDate),_xlpm.bodyCode,MID(_xlpm.vin,6,2),_xlpm.yearCode,MID(_xlpm.vin,10,1),IF(OR(LEN(_xlpm.vin)<>10,LEN(_xlpm.rawDate)<>8),"UNKNOWN",IF(OR(_xlpm.bodyCode="43",_xlpm.bodyCode="4D",_xlpm.bodyCode="44",_xlpm.bodyCode="4E",_xlpm.bodyCode="45",_xlpm.bodyCode="4F",_xlpm.bodyCode="46",_xlpm.bodyCode="4G",_xlpm.bodyCode="47"),_xlfn.SWITCH(_xlpm.yearCode,"6","B00379–B06783","7","B06784–B20074","8","B20075–B27986","9","B27987–B32752","A","B32753–B38853","B","B38854–B44939","C","B44940–B48619","D","B48620–B54164","E","B54165–B56794","F","B56795+","UNKNOWN"),IF(_xlpm.useDate<"19960601","001001–001245",IF(_xlpm.useDate<"19970101","001246–008106",IF(_xlpm.useDate<"19970801","008107–018107",IF(_xlpm.useDate<"19980101","018108–023017",IF(_xlpm.useDate<"19980201","023018–024686",IF(_xlpm.useDate<"19980801","024687–031302",IF(_xlpm.useDate<"19990801","031303–036193",IF(_xlpm.useDate<"20010101","036194–042775",IF(OR(_xlpm.bodyCode="41",_xlpm.bodyCode="42"),_xlfn.SWITCH(_xlpm.yearCode,"Y","A00001–A11050","1","A11051–A22928","2","A22929–A30644","3","A30645–A36873","4","A36874–A42347","5","A42348–A48684","UNKNOWN"),"UNKNOWN"))))))))))))} -> 001246–008106 | E3: ='Ajoneuvorekisteri-Parse Modern '!G149 -> 19961113 | F3: =LEFT(Table34[[#This Row],[Käyttöönotto]],4) -> 1996 | G3: ='Ajoneuvorekisteri-Parse Modern '!AA149 -> XK8 Avoauto (AE) 2ov 3990cm3 A | H3: =Ajoneuvorekisteri_Parse_Modern_XK_Range_TieliikenneAvoinData_30_06_2026_csv[[#This Row],[tyyppihyvaksyntanro]] -> e11*2001/116*0272*01 | I3: ='Ajoneuvorekisteri-Parse Modern '!M149 -> 1720 | J3: =IF(AND( OR( ISNUMBER(SEARCH("XK ", G3)), ISNUMBER(SEARCH("XK8", G3)) ), F3 > 2005 ), 1, 0) -> 1 | K3: =IF(OR( ISNUMBER(SEARCH("XKR", G3)), ), 1, 0) -> 0 | L3: =IF(OR( ISNUMBER(SEARCH("COUPE", G3)), ISNUMBER(SEARCH("COUPÉ", G3)), ISNUMBER(SEARCH("COUP�", G3)) ), 1, 0) -> 0 | M3: =IF(OR( ISNUMBER(SEARCH("CONVERTIBLE",G3)), ISNUMBER(SEARCH("AVOAUTO",G3)), ISNUMBER(SEARCH("AVO",G3)), ISNUMBER(SEARCH("CABRIO",G3)) ),1,0) -> 1 | N3: =IF(AND(Table34[[#This Row],[Coupe]]<>1, Table34[[#This Row],[Convertible]]<>1), 1, 0) -> 0 | O3: =IF(L3=1, "Coupe", IF(M3=1, "Convertible", "Unknown")) -> Convertible
A4: ='Ajoneuvorekisteri-Parse Modern '!AO87 -> 2098581 | B4: ='Ajoneuvorekisteri-Parse Modern '!AN87 -> SAJJGAED4A | C4: {=_xlfn.LET(_xlpm.v,UPPER(SUBSTITUTE(CLEAN(TRIM(B4)),CHAR(160),"")),_xlpm.mkt,MID(_xlpm.v,4,1),_xlpm.trans,MID(_xlpm.v,5,1),_xlpm.body,MID(_xlpm.v,6,2),_xlpm.emis,MID(_xlpm.v,8,1),_xlpm.my,MID(_xlpm.v,10,1),_xlfn.IFS(AND(LEN(_xlpm.v)=10,LEFT(_xlpm.v,5)="SAJJG",OR(MID(_xlpm.v,7,1)="E",MID(_xlpm.v,7,1)="F"),OR(_xlpm.emis="D",_xlpm.emis="F"),OR(MID(_xlpm.v,9,1)="3",MID(_xlpm.v,9,1)="4"),_xlpm.my="A"),"X100_EARLY_NORMAL_AR (JDHT)",AND(LEN(_xlpm.v)=10,LEFT(_xlpm.v,5)="SAJJG",MID(_xlpm.v,6,1)="A",OR(MID(_xlpm.v,7,1)="E",MID(_xlpm.v,7,1)="F"),_xlpm.emis="D",OR(MID(_xlpm.v,9,1)="3",MID(_xlpm.v,9,1)="4"),OR(_xlpm.my="V",_xlpm.my="W",_xlpm.my="X")),"X100_NORMAL (JDHT)",AND(LEN(_xlpm.v)=10,LEFT(_xlpm.v,5)="SAJJG",OR(MID(_xlpm.v,6,1)="A",MID(_xlpm.v,6,1)="K",MID(_xlpm.v,6,1)="N",MID(_xlpm.v,6,1)="X"),OR(MID(_xlpm.v,7,1)="E",MID(_xlpm.v,7,1)="F"),OR(_xlpm.emis="D",_xlpm.emis="F"),OR(MID(_xlpm.v,9,1)="3",MID(_xlpm.v,9,1)="4"),OR(_xlpm.my="V",_xlpm.my="W",_xlpm.my="X")),"X100_JLM20300",AND(LEN(_xlpm.v)=10,LEFT(_xlpm.v,5)="SAJJG",OR(MID(_xlpm.v,6,1)="N",MID(_xlpm.v,6,1)="S",MID(_xlpm.v,6,1)="X"),OR(MID(_xlpm.v,7,1)="E",MID(_xlpm.v,7,1)="F"),OR(_xlpm.emis="D",_xlpm.emis="F"),OR(MID(_xlpm.v,9,1)="3",MID(_xlpm.v,9,1)="4"),OR(MID(_xlpm.v,10,1)="V",MID(_xlpm.v,10,1)="W",MID(_xlpm.v,10,1)="X")),"X100_JLM20301",AND(LEN(_xlpm.v)=10,LEFT(_xlpm.v,5)="SAJGX",OR(MID(_xlpm.v,6,1)="2",MID(_xlpm.v,6,1)="5"),OR(MID(_xlpm.v,7,1)="1",MID(_xlpm.v,7,1)="2",MID(_xlpm.v,7,1)="7"),MID(_xlpm.v,8,1)="4",OR(MID(_xlpm.v,10,1)="V",MID(_xlpm.v,10,1)="W",MID(_xlpm.v,10,1)="X")),"X100_AMERICAS_UNIQUE (JLM20301_unique)",AND(LEN(_xlpm.v)=10,LEFT(_xlpm.v,3)="SAJ",OR(_xlpm.mkt="A",_xlpm.mkt="B",_xlpm.mkt="F",_xlpm.mkt="G",_xlpm.mkt="X",_xlpm.mkt="P",_xlpm.mkt="R",_xlpm.mkt="T",_xlpm.mkt="Y",_xlpm.mkt="D",_xlpm.mkt="E",_xlpm.mkt="J",_xlpm.mkt="W"),OR(_xlpm.trans="A",_xlpm.trans="B"),OR(_xlpm.body="41",_xlpm.body="42"),IFERROR(AND(CODE(_xlpm.emis)>=65,CODE(_xlpm.emis)<=88),FALSE),OR(_xlpm.my="X",_xlpm.my="Y",_xlpm.my="1",_xlpm.my="2",_xlpm.my="3",_xlpm.my="4",_xlpm.my="5",_xlpm.my="6",_xlpm.my="7",_xlpm.my="8",_xlpm.my="9")),"XK8-XKR_"&IF(_xlpm.body="41","COUPE_","CONVERTIBLE_")&IF(ISNUMBER(FIND(_xlpm.mkt,"DEJW")),"USA",IF(ISNUMBER(FIND(_xlpm.mkt,"BFGX")),"CANADA","MEXICO"))&IF(_xlpm.trans="A","_AUTO_LHD","_MANUAL_LHD")&"_EMISSION_"&_xlpm.emis&IF(_xlpm.my="X","_1999",IF(_xlpm.my="Y","_2000","_200"&_xlpm.my))&"MY",AND(LEN(_xlpm.v)=10,LEFT(_xlpm.v,3)="SAJ",OR(_xlpm.mkt="A",_xlpm.mkt="B",_xlpm.mkt="D",_xlpm.mkt="E",_xlpm.mkt="F",_xlpm.mkt="J",_xlpm.mkt="K",_xlpm.mkt="P",_xlpm.mkt="R",_xlpm.mkt="W",_xlpm.mkt="X",_xlpm.mkt="Y"),OR(_xlpm.trans="A",_xlpm.trans="C"),OR(_xlpm.body="43",_xlpm.body="4D",_xlpm.body="44",_xlpm.body="4E",_xlpm.body="45",_xlpm.body="46",_xlpm.body="47",_xlpm.body="4F",_xlpm.body="4G"),OR(_xlpm.emis="A",_xlpm.emis="B",_xlpm.emis="C",_xlpm.emis="D",_xlpm.emis="E",_xlpm.emis="F",_xlpm.emis="G",_xlpm.emis="K",_xlpm.emis="N",_xlpm.emis="P",_xlpm.emis="R",_xlpm.emis="S",_xlpm.emis="T",_xlpm.emis="U",_xlpm.emis="V",_xlpm.emis="W",_xlpm.emis="X",_xlpm.emis="Y",_xlpm.emis="1",_xlpm.emis="2",_xlpm.emis="3",_xlpm.emis="4"),OR(_xlpm.my="7",_xlpm.my="8",_xlpm.my="9",_xlpm.my="A",_xlpm.my="B",_xlpm.my="C",_xlpm.my="D",_xlpm.my="E")),"X150_"&IF(_xlpm.my="7","2007MY",IF(_xlpm.my="8","2008MY",IF(_xlpm.my="9","2009MY",IF(_xlpm.my="A","2010MY",IF(_xlpm.my="B","2011MY",IF(_xlpm.my="C","2012MY",IF(_xlpm.my="D","2013MY",IF(_xlpm.my="E","2014MY","UNKNOWN_MY"))))))))&"_MARKET_"&_xlpm.mkt&"_TRANS_"&_xlpm.trans&"_BODY_"&_xlpm.body&"_EMISSION_"&_xlpm.emis&"_CHECK_"&MID(_xlpm.v,9,1),TRUE,IF(LEN(_xlpm.v)<>10,"UNKNOWN: [length="&LEN(_xlpm.v)&"]",IF(LEFT(_xlpm.v,3)<>"SAJ","UNKNOWN: [prefix="&LEFT(_xlpm.v,3)&"]",IF(LEFT(_xlpm.v,5)="SAJJG",IF(NOT(OR(MID(_xlpm.v,7,1)="E",MID(_xlpm.v,7,1)="F")),"UNKNOWN: [7="&MID(_xlpm.v,7,1)&"]",IF(NOT(OR(_xlpm.emis="D",_xlpm.emis="F")),"UNKNOWN: [8="&_xlpm.emis&"]",IF(NOT(OR(MID(_xlpm.v,9,1)="3",MID(_xlpm.v,9,1)="4")),"UNKNOWN: [9="&MID(_xlpm.v,9,1)&"]",IF(NOT(OR(_xlpm.my="A",_xlpm.my="V",_xlpm.my="W",_xlpm.my="X")),"UNKNOWN: [10="&_xlpm.my&"]","UNKNOWN")))),IF(LEFT(_xlpm.v,5)="SAJGX",IF(NOT(OR(MID(_xlpm.v,6,1)="2",MID(_xlpm.v,6,1)="5")),"UNKNOWN: [6="&MID(_xlpm.v,6,1)&"]",IF(NOT(OR(MID(_xlpm.v,7,1)="1",MID(_xlpm.v,7,1)="2",MID(_xlpm.v,7,1)="7")),"UNKNOWN: [7="&MID(_xlpm.v,7,1)&"]",IF(MID(_xlpm.v,8,1)<>"4","UNKNOWN: [8="&MID(_xlpm.v,8,1)&"]",IF(NOT(OR(_xlpm.my="V",_xlpm.my="W",_xlpm.my="X")),"UNKNOWN: [10="&_xlpm.my&"]","UNKNOWN")))),IF(NOT(OR(_xlpm.mkt="A",_xlpm.mkt="B",_xlpm.mkt="F",_xlpm.mkt="G",_xlpm.mkt="X",_xlpm.mkt="P",_xlpm.mkt="R",_xlpm.mkt="T",_xlpm.mkt="Y",_xlpm.mkt="D",_xlpm.mkt="E",_xlpm.mkt="J",_xlpm.mkt="W",_xlpm.mkt="K")),"UNKNOWN: [4="&_xlpm.mkt&"]",IF(NOT(OR(_xlpm.trans="A",_xlpm.trans="B",_xlpm.trans="C")),"UNKNOWN: [5="&_xlpm.trans&"]",IF(NOT(OR(_xlpm.body="41",_xlpm.body="42",_xlpm.body="43",_xlpm.body="4D",_xlpm.body="44",_xlpm.body="45",_xlpm.body="46",_xlpm.body="47",_xlpm.body="4F")),"UNKNOWN: [6-7="&_xlpm.body&"]",IF(NOT(ISNUMBER(SEARCH(_xlpm.emis,"ABCDEFGKNPRSTUVWXY1234"))),"UNKNOWN: [8="&_xlpm.emis&"]",IF(NOT(OR(_xlpm.my="X",_xlpm.my="Y",_xlpm.my="1",_xlpm.my="2",_xlpm.my="3",_xlpm.my="4",_xlpm.my="5",_xlpm.my="6",_xlpm.my="7",_xlpm.my="8",_xlpm.my="9",_xlpm.my="A",_xlpm.my="B",_xlpm.my="C",_xlpm.my="D",_xlpm.my="E")),"UNKNOWN: [10="&_xlpm.my&"]","UNKNOWN")))))))))))} -> X100_EARLY_NORMAL_AR (JDHT) | D4: {=_xlfn.LET(_xlpm.vin,SUBSTITUTE(CLEAN(TRIM(B4)),CHAR(160),""),_xlpm.rawDate,LEFT(TRIM(E4)&"",8),_xlpm.useDate,IF(RIGHT(_xlpm.rawDate,4)="0000",LEFT(_xlpm.rawDate,4)&"1231",_xlpm.rawDate),_xlpm.bodyCode,MID(_xlpm.vin,6,2),_xlpm.yearCode,MID(_xlpm.vin,10,1),IF(OR(LEN(_xlpm.vin)<>10,LEN(_xlpm.rawDate)<>8),"UNKNOWN",IF(OR(_xlpm.bodyCode="43",_xlpm.bodyCode="4D",_xlpm.bodyCode="44",_xlpm.bodyCode="4E",_xlpm.bodyCode="45",_xlpm.bodyCode="4F",_xlpm.bodyCode="46",_xlpm.bodyCode="4G",_xlpm.bodyCode="47"),_xlfn.SWITCH(_xlpm.yearCode,"6","B00379–B06783","7","B06784–B20074","8","B20075–B27986","9","B27987–B32752","A","B32753–B38853","B","B38854–B44939","C","B44940–B48619","D","B48620–B54164","E","B54165–B56794","F","B56795+","UNKNOWN"),IF(_xlpm.useDate<"19960601","001001–001245",IF(_xlpm.useDate<"19970101","001246–008106",IF(_xlpm.useDate<"19970801","008107–018107",IF(_xlpm.useDate<"19980101","018108–023017",IF(_xlpm.useDate<"19980201","023018–024686",IF(_xlpm.useDate<"19980801","024687–031302",IF(_xlpm.useDate<"19990801","031303–036193",IF(_xlpm.useDate<"20010101","036194–042775",IF(OR(_xlpm.bodyCode="41",_xlpm.bodyCode="42"),_xlfn.SWITCH(_xlpm.yearCode,"Y","A00001–A11050","1","A11051–A22928","2","A22929–A30644","3","A30645–A36873","4","A36874–A42347","5","A42348–A48684","UNKNOWN"),"UNKNOWN"))))))))))))} -> 001246–008106 | E4: ='Ajoneuvorekisteri-Parse Modern '!G87 -> 19961219 | F4: =LEFT(Table34[[#This Row],[Käyttöönotto]],4) -> 1996 | G4: ='Ajoneuvorekisteri-Parse Modern '!AA87 -> XK Coup� (AD) 2ov 3990cm3 A | H4: =Ajoneuvorekisteri_Parse_Modern_XK_Range_TieliikenneAvoinData_30_06_2026_csv[[#This Row],[tyyppihyvaksyntanro]] | I4: ='Ajoneuvorekisteri-Parse Modern '!M87 -> 1720 | J4: =IF(AND( OR( ISNUMBER(SEARCH("XK ", G4)), ISNUMBER(SEARCH("XK8", G4)) ), F4 > 2005 ), 1, 0) -> 1 | K4: =IF(OR( ISNUMBER(SEARCH("XKR", G4)), ), 1, 0) -> 0 | L4: =IF(OR( ISNUMBER(SEARCH("COUPE", G4)), ISNUMBER(SEARCH("COUPÉ", G4)), ISNUMBER(SEARCH("COUP�", G4)) ), 1, 0) -> 1 | M4: =IF(OR( ISNUMBER(SEARCH("CONVERTIBLE",G4)), ISNUMBER(SEARCH("AVOAUTO",G4)), ISNUMBER(SEARCH("AVO",G4)), ISNUMBER(SEARCH("CABRIO",G4)) ),1,0) -> 0 | N4: =IF(AND(Table34[[#This Row],[Coupe]]<>1, Table34[[#This Row],[Convertible]]<>1), 1, 0) -> 0 | O4: =IF(L4=1, "Coupe", IF(M4=1, "Convertible", "Unknown")) -> Coupe
A5: ='Ajoneuvorekisteri-Parse Modern '!AO11 -> 301741 | B5: ='Ajoneuvorekisteri-Parse Modern '!AN11 -> SAJJGXFD4V | C5: {=_xlfn.LET(_xlpm.v,UPPER(SUBSTITUTE(CLEAN(TRIM(B5)),CHAR(160),"")),_xlpm.mkt,MID(_xlpm.v,4,1),_xlpm.trans,MID(_xlpm.v,5,1),_xlpm.body,MID(_xlpm.v,6,2),_xlpm.emis,MID(_xlpm.v,8,1),_xlpm.my,MID(_xlpm.v,10,1),_xlfn.IFS(AND(LEN(_xlpm.v)=10,LEFT(_xlpm.v,5)="SAJJG",OR(MID(_xlpm.v,7,1)="E",MID(_xlpm.v,7,1)="F"),OR(_xlpm.emis="D",_xlpm.emis="F"),OR(MID(_xlpm.v,9,1)="3",MID(_xlpm.v,9,1)="4"),_xlpm.my="A"),"X100_EARLY_NORMAL_AR (JDHT)",AND(LEN(_xlpm.v)=10,LEFT(_xlpm.v,5)="SAJJG",MID(_xlpm.v,6,1)="A",OR(MID(_xlpm.v,7,1)="E",MID(_xlpm.v,7,1)="F"),_xlpm.emis="D",OR(MID(_xlpm.v,9,1)="3",MID(_xlpm.v,9,1)="4"),OR(_xlpm.my="V",_xlpm.my="W",_xlpm.my="X")),"X100_NORMAL (JDHT)",AND(LEN(_xlpm.v)=10,LEFT(_xlpm.v,5)="SAJJG",OR(MID(_xlpm.v,6,1)="A",MID(_xlpm.v,6,1)="K",MID(_xlpm.v,6,1)="N",MID(_xlpm.v,6,1)="X"),OR(MID(_xlpm.v,7,1)="E",MID(_xlpm.v,7,1)="F"),OR(_xlpm.emis="D",_xlpm.emis="F"),OR(MID(_xlpm.v,9,1)="3",MID(_xlpm.v,9,1)="4"),OR(_xlpm.my="V",_xlpm.my="W",_xlpm.my="X")),"X100_JLM20300",AND(LEN(_xlpm.v)=10,LEFT(_xlpm.v,5)="SAJJG",OR(MID(_xlpm.v,6,1)="N",MID(_xlpm.v,6,1)="S",MID(_xlpm.v,6,1)="X"),OR(MID(_xlpm.v,7,1)="E",MID(_xlpm.v,7,1)="F"),OR(_xlpm.emis="D",_xlpm.emis="F"),OR(MID(_xlpm.v,9,1)="3",MID(_xlpm.v,9,1)="4"),OR(MID(_xlpm.v,10,1)="V",MID(_xlpm.v,10,1)="W",MID(_xlpm.v,10,1)="X")),"X100_JLM20301",AND(LEN(_xlpm.v)=10,LEFT(_xlpm.v,5)="SAJGX",OR(MID(_xlpm.v,6,1)="2",MID(_xlpm.v,6,1)="5"),OR(MID(_xlpm.v,7,1)="1",MID(_xlpm.v,7,1)="2",MID(_xlpm.v,7,1)="7"),MID(_xlpm.v,8,1)="4",OR(MID(_xlpm.v,10,1)="V",MID(_xlpm.v,10,1)="W",MID(_xlpm.v,10,1)="X")),"X100_AMERICAS_UNIQUE (JLM20301_unique)",AND(LEN(_xlpm.v)=10,LEFT(_xlpm.v,3)="SAJ",OR(_xlpm.mkt="A",_xlpm.mkt="B",_xlpm.mkt="F",_xlpm.mkt="G",_xlpm.mkt="X",_xlpm.mkt="P",_xlpm.mkt="R",_xlpm.mkt="T",_xlpm.mkt="Y",_xlpm.mkt="D",_xlpm.mkt="E",_xlpm.mkt="J",_xlpm.mkt="W"),OR(_xlpm.trans="A",_xlpm.trans="B"),OR(_xlpm.body="41",_xlpm.body="42"),IFERROR(AND(CODE(_xlpm.emis)>=65,CODE(_xlpm.emis)<=88),FALSE),OR(_xlpm.my="X",_xlpm.my="Y",_xlpm.my="1",_xlpm.my="2",_xlpm.my="3",_xlpm.my="4",_xlpm.my="5",_xlpm.my="6",_xlpm.my="7",_xlpm.my="8",_xlpm.my="9")),"XK8-XKR_"&IF(_xlpm.body="41","COUPE_","CONVERTIBLE_")&IF(ISNUMBER(FIND(_xlpm.mkt,"DEJW")),"USA",IF(ISNUMBER(FIND(_xlpm.mkt,"BFGX")),"CANADA","MEXICO"))&IF(_xlpm.trans="A","_AUTO_LHD","_MANUAL_LHD")&"_EMISSION_"&_xlpm.emis&IF(_xlpm.my="X","_1999",IF(_xlpm.my="Y","_2000","_200"&_xlpm.my))&"MY",AND(LEN(_xlpm.v)=10,LEFT(_xlpm.v,3)="SAJ",OR(_xlpm.mkt="A",_xlpm.mkt="B",_xlpm.mkt="D",_xlpm.mkt="E",_xlpm.mkt="F",_xlpm.mkt="J",_xlpm.mkt="K",_xlpm.mkt="P",_xlpm.mkt="R",_xlpm.mkt="W",_xlpm.mkt="X",_xlpm.mkt="Y"),OR(_xlpm.trans="A",_xlpm.trans="C"),OR(_xlpm.body="43",_xlpm.body="4D",_xlpm.body="44",_xlpm.body="4E",_xlpm.body="45",_xlpm.body="46",_xlpm.body="47",_xlpm.body="4F",_xlpm.body="4G"),OR(_xlpm.emis="A",_xlpm.emis="B",_xlpm.emis="C",_xlpm.emis="D",_xlpm.emis="E",_xlpm.emis="F",_xlpm.emis="G",_xlpm.emis="K",_xlpm.emis="N",_xlpm.emis="P",_xlpm.emis="R",_xlpm.emis="S",_xlpm.emis="T",_xlpm.emis="U",_xlpm.emis="V",_xlpm.emis="W",_xlpm.emis="X",_xlpm.emis="Y",_xlpm.emis="1",_xlpm.emis="2",_xlpm.emis="3",_xlpm.emis="4"),OR(_xlpm.my="7",_xlpm.my="8",_xlpm.my="9",_xlpm.my="A",_xlpm.my="B",_xlpm.my="C",_xlpm.my="D",_xlpm.my="E")),"X150_"&IF(_xlpm.my="7","2007MY",IF(_xlpm.my="8","2008MY",IF(_xlpm.my="9","2009MY",IF(_xlpm.my="A","2010MY",IF(_xlpm.my="B","2011MY",IF(_xlpm.my="C","2012MY",IF(_xlpm.my="D","2013MY",IF(_xlpm.my="E","2014MY","UNKNOWN_MY"))))))))&"_MARKET_"&_xlpm.mkt&"_TRANS_"&_xlpm.trans&"_BODY_"&_xlpm.body&"_EMISSION_"&_xlpm.emis&"_CHECK_"&MID(_xlpm.v,9,1),TRUE,IF(LEN(_xlpm.v)<>10,"UNKNOWN: [length="&LEN(_xlpm.v)&"]",IF(LEFT(_xlpm.v,3)<>"SAJ","UNKNOWN: [prefix="&LEFT(_xlpm.v,3)&"]",IF(LEFT(_xlpm.v,5)="SAJJG",IF(NOT(OR(MID(_xlpm.v,7,1)="E",MID(_xlpm.v,7,1)="F")),"UNKNOWN: [7="&MID(_xlpm.v,7,1)&"]",IF(NOT(OR(_xlpm.emis="D",_xlpm.emis="F")),"UNKNOWN: [8="&_xlpm.emis&"]",IF(NOT(OR(MID(_xlpm.v,9,1)="3",MID(_xlpm.v,9,1)="4")),"UNKNOWN: [9="&MID(_xlpm.v,9,1)&"]",IF(NOT(OR(_xlpm.my="A",_xlpm.my="V",_xlpm.my="W",_xlpm.my="X")),"UNKNOWN: [10="&_xlpm.my&"]","UNKNOWN")))),IF(LEFT(_xlpm.v,5)="SAJGX",IF(NOT(OR(MID(_xlpm.v,6,1)="2",MID(_xlpm.v,6,1)="5")),"UNKNOWN: [6="&MID(_xlpm.v,6,1)&"]",IF(NOT(OR(MID(_xlpm.v,7,1)="1",MID(_xlpm.v,7,1)="2",MID(_xlpm.v,7,1)="7")),"UNKNOWN: [7="&MID(_xlpm.v,7,1)&"]",IF(MID(_xlpm.v,8,1)<>"4","UNKNOWN: [8="&MID(_xlpm.v,8,1)&"]",IF(NOT(OR(_xlpm.my="V",_xlpm.my="W",_xlpm.my="X")),"UNKNOWN: [10="&_xlpm.my&"]","UNKNOWN")))),IF(NOT(OR(_xlpm.mkt="A",_xlpm.mkt="B",_xlpm.mkt="F",_xlpm.mkt="G",_xlpm.mkt="X",_xlpm.mkt="P",_xlpm.mkt="R",_xlpm.mkt="T",_xlpm.mkt="Y",_xlpm.mkt="D",_xlpm.mkt="E",_xlpm.mkt="J",_xlpm.mkt="W",_xlpm.mkt="K")),"UNKNOWN: [4="&_xlpm.mkt&"]",IF(NOT(OR(_xlpm.trans="A",_xlpm.trans="B",_xlpm.trans="C")),"UNKNOWN: [5="&_xlpm.trans&"]",IF(NOT(OR(_xlpm.body="41",_xlpm.body="42",_xlpm.body="43",_xlpm.body="4D",_xlpm.body="44",_xlpm.body="45",_xlpm.body="46",_xlpm.body="47",_xlpm.body="4F")),"UNKNOWN: [6-7="&_xlpm.body&"]",IF(NOT(ISNUMBER(SEARCH(_xlpm.emis,"ABCDEFGKNPRSTUVWXY1234"))),"UNKNOWN: [8="&_xlpm.emis&"]",IF(NOT(OR(_xlpm.my="X",_xlpm.my="Y",_xlpm.my="1",_xlpm.my="2",_xlpm.my="3",_xlpm.my="4",_xlpm.my="5",_xlpm.my="6",_xlpm.my="7",_xlpm.my="8",_xlpm.my="9",_xlpm.my="A",_xlpm.my="B",_xlpm.my="C",_xlpm.my="D",_xlpm.my="E")),"UNKNOWN: [10="&_xlpm.my&"]","UNKNOWN")))))))))))} -> X100_JLM20300 | D5: {=_xlfn.LET(_xlpm.vin,SUBSTITUTE(CLEAN(TRIM(B5)),CHAR(160),""),_xlpm.rawDate,LEFT(TRIM(E5)&"",8),_xlpm.useDate,IF(RIGHT(_xlpm.rawDate,4)="0000",LEFT(_xlpm.rawDate,4)&"1231",_xlpm.rawDate),_xlpm.bodyCode,MID(_xlpm.vin,6,2),_xlpm.yearCode,MID(_xlpm.vin,10,1),IF(OR(LEN(_xlpm.vin)<>10,LEN(_xlpm.rawDate)<>8),"UNKNOWN",IF(OR(_xlpm.bodyCode="43",_xlpm.bodyCode="4D",_xlpm.bodyCode="44",_xlpm.bodyCode="4E",_xlpm.bodyCode="45",_xlpm.bodyCode="4F",_xlpm.bodyCode="46",_xlpm.bodyCode="4G",_xlpm.bodyCode="47"),_xlfn.SWITCH(_xlpm.yearCode,"6","B00379–B06783","7","B06784–B20074","8","B20075–B27986","9","B27987–B32752","A","B32753–B38853","B","B38854–B44939","C","B44940–B48619","D","B48620–B54164","E","B54165–B56794","F","B56795+","UNKNOWN"),IF(_xlpm.useDate<"19960601","001001–001245",IF(_xlpm.useDate<"19970101","001246–008106",IF(_xlpm.useDate<"19970801","008107–018107",IF(_xlpm.useDate<"19980101","018108–023017",IF(_xlpm.useDate<"19980201","023018–024686",IF(_xlpm.useDate<"19980801","024687–031302",IF(_xlpm.useDate<"19990801","031303–036193",IF(_xlpm.useDate<"20010101","036194–042775",IF(OR(_xlpm.bodyCode="41",_xlpm.bodyCode="42"),_xlfn.SWITCH(_xlpm.yearCode,"Y","A00001–A11050","1","A11051–A22928","2","A22929–A30644","3","A30645–A36873","4","A36874–A42347","5","A42348–A48684","UNKNOWN"),"UNKNOWN"))))))))))))} -> 018108–023017 | E5: ='Ajoneuvorekisteri-Parse Modern '!G11 -> 19970000 | F5: =LEFT(Table34[[#This Row],[Käyttöönotto]],4) -> 1997 | G5: ='Ajoneuvorekisteri-Parse Modern '!AA11 -> 2D CONVERTIBLE XK8 4.0-AUTOMATIC-JGFD/259 | H5: =Ajoneuvorekisteri_Parse_Modern_XK_Range_TieliikenneAvoinData_30_06_2026_csv[[#This Row],[tyyppihyvaksyntanro]] -> e11*95/54*0062*03 | I5: ='Ajoneuvorekisteri-Parse Modern '!M11 -> 1850 | J5: =IF(AND( OR( ISNUMBER(SEARCH("XK ", G5)), ISNUMBER(SEARCH("XK8", G5)) ), F5 > 2005 ), 1, 0) -> 1 | K5: =IF(OR( ISNUMBER(SEARCH("XKR", G5)), ), 1, 0) -> 0 | L5: =IF(OR( ISNUMBER(SEARCH("COUPE", G5)), ISNUMBER(SEARCH("COUPÉ", G5)), ISNUMBER(SEARCH("COUP�", G5)) ), 1, 0) -> 0 | M5: =IF(OR( ISNUMBER(SEARCH("CONVERTIBLE",G5)), ISNUMBER(SEARCH("AVOAUTO",G5)), ISNUMBER(SEARCH("AVO",G5)), ISNUMBER(SEARCH("CABRIO",G5)) ),1,0) -> 1 | N5: =IF(AND(Table34[[#This Row],[Coupe]]<>1, Table34[[#This Row],[Convertible]]<>1), 1, 0) -> 0 | O5: =IF(L5=1, "Coupe", IF(M5=1, "Convertible", "Unknown")) -> Convertible
A6: ='Ajoneuvorekisteri-Parse Modern '!AO22 -> 755631 | B6: ='Ajoneuvorekisteri-Parse Modern '!AN22 -> SAJJGFXD4V | C6: {=_xlfn.LET(_xlpm.v,UPPER(SUBSTITUTE(CLEAN(TRIM(B6)),CHAR(160),"")),_xlpm.mkt,MID(_xlpm.v,4,1),_xlpm.trans,MID(_xlpm.v,5,1),_xlpm.body,MID(_xlpm.v,6,2),_xlpm.emis,MID(_xlpm.v,8,1),_xlpm.my,MID(_xlpm.v,10,1),_xlfn.IFS(AND(LEN(_xlpm.v)=10,LEFT(_xlpm.v,5)="SAJJG",OR(MID(_xlpm.v,7,1)="E",MID(_xlpm.v,7,1)="F"),OR(_xlpm.emis="D",_xlpm.emis="F"),OR(MID(_xlpm.v,9,1)="3",MID(_xlpm.v,9,1)="4"),_xlpm.my="A"),"X100_EARLY_NORMAL_AR (JDHT)",AND(LEN(_xlpm.v)=10,LEFT(_xlpm.v,5)="SAJJG",MID(_xlpm.v,6,1)="A",OR(MID(_xlpm.v,7,1)="E",MID(_xlpm.v,7,1)="F"),_xlpm.emis="D",OR(MID(_xlpm.v,9,1)="3",MID(_xlpm.v,9,1)="4"),OR(_xlpm.my="V",_xlpm.my="W",_xlpm.my="X")),"X100_NORMAL (JDHT)",AND(LEN(_xlpm.v)=10,LEFT(_xlpm.v,5)="SAJJG",OR(MID(_xlpm.v,6,1)="A",MID(_xlpm.v,6,1)="K",MID(_xlpm.v,6,1)="N",MID(_xlpm.v,6,1)="X"),OR(MID(_xlpm.v,7,1)="E",MID(_xlpm.v,7,1)="F"),OR(_xlpm.emis="D",_xlpm.emis="F"),OR(MID(_xlpm.v,9,1)="3",MID(_xlpm.v,9,1)="4"),OR(_xlpm.my="V",_xlpm.my="W",_xlpm.my="X")),"X100_JLM20300",AND(LEN(_xlpm.v)=10,LEFT(_xlpm.v,5)="SAJJG",OR(MID(_xlpm.v,6,1)="N",MID(_xlpm.v,6,1)="S",MID(_xlpm.v,6,1)="X"),OR(MID(_xlpm.v,7,1)="E",MID(_xlpm.v,7,1)="F"),OR(_xlpm.emis="D",_xlpm.emis="F"),OR(MID(_xlpm.v,9,1)="3",MID(_xlpm.v,9,1)="4"),OR(MID(_xlpm.v,10,1)="V",MID(_xlpm.v,10,1)="W",MID(_xlpm.v,10,1)="X")),"X100_JLM20301",AND(LEN(_xlpm.v)=10,LEFT(_xlpm.v,5)="SAJGX",OR(MID(_xlpm.v,6,1)="2",MID(_xlpm.v,6,1)="5"),OR(MID(_xlpm.v,7,1)="1",MID(_xlpm.v,7,1)="2",MID(_xlpm.v,7,1)="7"),MID(_xlpm.v,8,1)="4",OR(MID(_xlpm.v,10,1)="V",MID(_xlpm.v,10,1)="W",MID(_xlpm.v,10,1)="X")),"X100_AMERICAS_UNIQUE (JLM20301_unique)",AND(LEN(_xlpm.v)=10,LEFT(_xlpm.v,3)="SAJ",OR(_xlpm.mkt="A",_xlpm.mkt="B",_xlpm.mkt="F",_xlpm.mkt="G",_xlpm.mkt="X",_xlpm.mkt="P",_xlpm.mkt="R",_xlpm.mkt="T",_xlpm.mkt="Y",_xlpm.mkt="D",_xlpm.mkt="E",_xlpm.mkt="J",_xlpm.mkt="W"),OR(_xlpm.trans="A",_xlpm.trans="B"),OR(_xlpm.body="41",_xlpm.body="42"),IFERROR(AND(CODE(_xlpm.emis)>=65,CODE(_xlpm.emis)<=88),FALSE),OR(_xlpm.my="X",_xlpm.my="Y",_xlpm.my="1",_xlpm.my="2",_xlpm.my="3",_xlpm.my="4",_xlpm.my="5",_xlpm.my="6",_xlpm.my="7",_xlpm.my="8",_xlpm.my="9")),"XK8-XKR_"&IF(_xlpm.body="41","COUPE_","CONVERTIBLE_")&IF(ISNUMBER(FIND(_xlpm.mkt,"DEJW")),"USA",IF(ISNUMBER(FIND(_xlpm.mkt,"BFGX")),"CANADA","MEXICO"))&IF(_xlpm.trans="A","_AUTO_LHD","_MANUAL_LHD")&"_EMISSION_"&_xlpm.emis&IF(_xlpm.my="X","_1999",IF(_xlpm.my="Y","_2000","_200"&_xlpm.my))&"MY",AND(LEN(_xlpm.v)=10,LEFT(_xlpm.v,3)="SAJ",OR(_xlpm.mkt="A",_xlpm.mkt="B",_xlpm.mkt="D",_xlpm.mkt="E",_xlpm.mkt="F",_xlpm.mkt="J",_xlpm.mkt="K",_xlpm.mkt="P",_xlpm.mkt="R",_xlpm.mkt="W",_xlpm.mkt="X",_xlpm.mkt="Y"),OR(_xlpm.trans="A",_xlpm.trans="C"),OR(_xlpm.body="43",_xlpm.body="4D",_xlpm.body="44",_xlpm.body="4E",_xlpm.body="45",_xlpm.body="46",_xlpm.body="47",_xlpm.body="4F",_xlpm.body="4G"),OR(_xlpm.emis="A",_xlpm.emis="B",_xlpm.emis="C",_xlpm.emis="D",_xlpm.emis="E",_xlpm.emis="F",_xlpm.emis="G",_xlpm.emis="K",_xlpm.emis="N",_xlpm.emis="P",_xlpm.emis="R",_xlpm.emis="S",_xlpm.emis="T",_xlpm.emis="U",_xlpm.emis="V",_xlpm.emis="W",_xlpm.emis="X",_xlpm.emis="Y",_xlpm.emis="1",_xlpm.emis="2",_xlpm.emis="3",_xlpm.emis="4"),OR(_xlpm.my="7",_xlpm.my="8",_xlpm.my="9",_xlpm.my="A",_xlpm.my="B",_xlpm.my="C",_xlpm.my="D",_xlpm.my="E")),"X150_"&IF(_xlpm.my="7","2007MY",IF(_xlpm.my="8","2008MY",IF(_xlpm.my="9","2009MY",IF(_xlpm.my="A","2010MY",IF(_xlpm.my="B","2011MY",IF(_xlpm.my="C","2012MY",IF(_xlpm.my="D","2013MY",IF(_xlpm.my="E","2014MY","UNKNOWN_MY"))))))))&"_MARKET_"&_xlpm.mkt&"_TRANS_"&_xlpm.trans&"_BODY_"&_xlpm.body&"_EMISSION_"&_xlpm.emis&"_CHECK_"&MID(_xlpm.v,9,1),TRUE,IF(LEN(_xlpm.v)<>10,"UNKNOWN: [length="&LEN(_xlpm.v)&"]",IF(LEFT(_xlpm.v,3)<>"SAJ","UNKNOWN: [prefix="&LEFT(_xlpm.v,3)&"]",IF(LEFT(_xlpm.v,5)="SAJJG",IF(NOT(OR(MID(_xlpm.v,7,1)="E",MID(_xlpm.v,7,1)="F")),"UNKNOWN: [7="&MID(_xlpm.v,7,1)&"]",IF(NOT(OR(_xlpm.emis="D",_xlpm.emis="F")),"UNKNOWN: [8="&_xlpm.emis&"]",IF(NOT(OR(MID(_xlpm.v,9,1)="3",MID(_xlpm.v,9,1)="4")),"UNKNOWN: [9="&MID(_xlpm.v,9,1)&"]",IF(NOT(OR(_xlpm.my="A",_xlpm.my="V",_xlpm.my="W",_xlpm.my="X")),"UNKNOWN: [10="&_xlpm.my&"]","UNKNOWN")))),IF(LEFT(_xlpm.v,5)="SAJGX",IF(NOT(OR(MID(_xlpm.v,6,1)="2",MID(_xlpm.v,6,1)="5")),"UNKNOWN: [6="&MID(_xlpm.v,6,1)&"]",IF(NOT(OR(MID(_xlpm.v,7,1)="1",MID(_xlpm.v,7,1)="2",MID(_xlpm.v,7,1)="7")),"UNKNOWN: [7="&MID(_xlpm.v,7,1)&"]",IF(MID(_xlpm.v,8,1)<>"4","UNKNOWN: [8="&MID(_xlpm.v,8,1)&"]",IF(NOT(OR(_xlpm.my="V",_xlpm.my="W",_xlpm.my="X")),"UNKNOWN: [10="&_xlpm.my&"]","UNKNOWN")))),IF(NOT(OR(_xlpm.mkt="A",_xlpm.mkt="B",_xlpm.mkt="F",_xlpm.mkt="G",_xlpm.mkt="X",_xlpm.mkt="P",_xlpm.mkt="R",_xlpm.mkt="T",_xlpm.mkt="Y",_xlpm.mkt="D",_xlpm.mkt="E",_xlpm.mkt="J",_xlpm.mkt="W",_xlpm.mkt="K")),"UNKNOWN: [4="&_xlpm.mkt&"]",IF(NOT(OR(_xlpm.trans="A",_xlpm.trans="B",_xlpm.trans="C")),"UNKNOWN: [5="&_xlpm.trans&"]",IF(NOT(OR(_xlpm.body="41",_xlpm.body="42",_xlpm.body="43",_xlpm.body="4D",_xlpm.body="44",_xlpm.body="45",_xlpm.body="46",_xlpm.body="47",_xlpm.body="4F")),"UNKNOWN: [6-7="&_xlpm.body&"]",IF(NOT(ISNUMBER(SEARCH(_xlpm.emis,"ABCDEFGKNPRSTUVWXY1234"))),"UNKNOWN: [8="&_xlpm.emis&"]",IF(NOT(OR(_xlpm.my="X",_xlpm.my="Y",_xlpm.my="1",_xlpm.my="2",_xlpm.my="3",_xlpm.my="4",_xlpm.my="5",_xlpm.my="6",_xlpm.my="7",_xlpm.my="8",_xlpm.my="9",_xlpm.my="A",_xlpm.my="B",_xlpm.my="C",_xlpm.my="D",_xlpm.my="E")),"UNKNOWN: [10="&_xlpm.my&"]","UNKNOWN")))))))))))} -> UNKNOWN: [7=X] | D6: {=_xlfn.LET(_xlpm.vin,SUBSTITUTE(CLEAN(TRIM(B6)),CHAR(160),""),_xlpm.rawDate,LEFT(TRIM(E6)&"",8),_xlpm.useDate,IF(RIGHT(_xlpm.rawDate,4)="0000",LEFT(_xlpm.rawDate,4)&"1231",_xlpm.rawDate),_xlpm.bodyCode,MID(_xlpm.vin,6,2),_xlpm.yearCode,MID(_xlpm.vin,10,1),IF(OR(LEN(_xlpm.vin)<>10,LEN(_xlpm.rawDate)<>8),"UNKNOWN",IF(OR(_xlpm.bodyCode="43",_xlpm.bodyCode="4D",_xlpm.bodyCode="44",_xlpm.bodyCode="4E",_xlpm.bodyCode="45",_xlpm.bodyCode="4F",_xlpm.bodyCode="46",_xlpm.bodyCode="4G",_xlpm.bodyCode="47"),_xlfn.SWITCH(_xlpm.yearCode,"6","B00379–B06783","7","B06784–B20074","8","B20075–B27986","9","B27987–B32752","A","B32753–B38853","B","B38854–B44939","C","B44940–B48619","D","B48620–B54164","E","B54165–B56794","F","B56795+","UNKNOWN"),IF(_xlpm.useDate<"19960601","001001–001245",IF(_xlpm.useDate<"19970101","001246–008106",IF(_xlpm.useDate<"19970801","008107–018107",IF(_xlpm.useDate<"19980101","018108–023017",IF(_xlpm.useDate<"19980201","023018–024686",IF(_xlpm.useDate<"19980801","024687–031302",IF(_xlpm.useDate<"19990801","031303–036193",IF(_xlpm.useDate<"20010101","036194–042775",IF(OR(_xlpm.bodyCode="41",_xlpm.bodyCode="42"),_xlfn.SWITCH(_xlpm.yearCode,"Y","A00001–A11050","1","A11051–A22928","2","A22929–A30644","3","A30645–A36873","4","A36874–A42347","5","A42348–A48684","UNKNOWN"),"UNKNOWN"))))))))))))} -> 018108–023017 | E6: ='Ajoneuvorekisteri-Parse Modern '!G22 -> 19970000 | F6: =LEFT(Table34[[#This Row],[Käyttöönotto]],4) -> 1997 | G6: ='Ajoneuvorekisteri-Parse Modern '!AA22 -> 2D CONVERTIBLE XK8 4.0-AUTOMATIC-JGFX/259 | H6: =Ajoneuvorekisteri_Parse_Modern_XK_Range_TieliikenneAvoinData_30_06_2026_csv[[#This Row],[tyyppihyvaksyntanro]] -> e11*95/54*0062*06 | I6: ='Ajoneuvorekisteri-Parse Modern '!M22 -> 1810 | J6: =IF(AND( OR( ISNUMBER(SEARCH("XK ", G6)), ISNUMBER(SEARCH("XK8", G6)) ), F6 > 2005 ), 1, 0) -> 1 | K6: =IF(OR( ISNUMBER(SEARCH("XKR", G6)), ), 1, 0) -> 0 | L6: =IF(OR( ISNUMBER(SEARCH("COUPE", G6)), ISNUMBER(SEARCH("COUPÉ", G6)), ISNUMBER(SEARCH("COUP�", G6)) ), 1, 0) -> 0 | M6: =IF(OR( ISNUMBER(SEARCH("CONVERTIBLE",G6)), ISNUMBER(SEARCH("AVOAUTO",G6)), ISNUMBER(SEARCH("AVO",G6)), ISNUMBER(SEARCH("CABRIO",G6)) ),1,0) -> 1 | N6: =IF(AND(Table34[[#This Row],[Coupe]]<>1, Table34[[#This Row],[Convertible]]<>1), 1, 0) -> 0 | O6: =IF(L6=1, "Coupe", IF(M6=1, "Convertible", "Unknown")) -> Convertible
A7: ='Ajoneuvorekisteri-Parse Modern '!AO73 -> 1946841 | B7: ='Ajoneuvorekisteri-Parse Modern '!AN73 -> SAJGX2740V | C7: {=_xlfn.LET(_xlpm.v,UPPER(SUBSTITUTE(CLEAN(TRIM(B7)),CHAR(160),"")),_xlpm.mkt,MID(_xlpm.v,4,1),_xlpm.trans,MID(_xlpm.v,5,1),_xlpm.body,MID(_xlpm.v,6,2),_xlpm.emis,MID(_xlpm.v,8,1),_xlpm.my,MID(_xlpm.v,10,1),_xlfn.IFS(AND(LEN(_xlpm.v)=10,LEFT(_xlpm.v,5)="SAJJG",OR(MID(_xlpm.v,7,1)="E",MID(_xlpm.v,7,1)="F"),OR(_xlpm.emis="D",_xlpm.emis="F"),OR(MID(_xlpm.v,9,1)="3",MID(_xlpm.v,9,1)="4"),_xlpm.my="A"),"X100_EARLY_NORMAL_AR (JDHT)",AND(LEN(_xlpm.v)=10,LEFT(_xlpm.v,5)="SAJJG",MID(_xlpm.v,6,1)="A",OR(MID(_xlpm.v,7,1)="E",MID(_xlpm.v,7,1)="F"),_xlpm.emis="D",OR(MID(_xlpm.v,9,1)="3",MID(_xlpm.v,9,1)="4"),OR(_xlpm.my="V",_xlpm.my="W",_xlpm.my="X")),"X100_NORMAL (JDHT)",AND(LEN(_xlpm.v)=10,LEFT(_xlpm.v,5)="SAJJG",OR(MID(_xlpm.v,6,1)="A",MID(_xlpm.v,6,1)="K",MID(_xlpm.v,6,1)="N",MID(_xlpm.v,6,1)="X"),OR(MID(_xlpm.v,7,1)="E",MID(_xlpm.v,7,1)="F"),OR(_xlpm.emis="D",_xlpm.emis="F"),OR(MID(_xlpm.v,9,1)="3",MID(_xlpm.v,9,1)="4"),OR(_xlpm.my="V",_xlpm.my="W",_xlpm.my="X")),"X100_JLM20300",AND(LEN(_xlpm.v)=10,LEFT(_xlpm.v,5)="SAJJG",OR(MID(_xlpm.v,6,1)="N",MID(_xlpm.v,6,1)="S",MID(_xlpm.v,6,1)="X"),OR(MID(_xlpm.v,7,1)="E",MID(_xlpm.v,7,1)="F"),OR(_xlpm.emis="D",_xlpm.emis="F"),OR(MID(_xlpm.v,9,1)="3",MID(_xlpm.v,9,1)="4"),OR(MID(_xlpm.v,10,1)="V",MID(_xlpm.v,10,1)="W",MID(_xlpm.v,10,1)="X")),"X100_JLM20301",AND(LEN(_xlpm.v)=10,LEFT(_xlpm.v,5)="SAJGX",OR(MID(_xlpm.v,6,1)="2",MID(_xlpm.v,6,1)="5"),OR(MID(_xlpm.v,7,1)="1",MID(_xlpm.v,7,1)="2",MID(_xlpm.v,7,1)="7"),MID(_xlpm.v,8,1)="4",OR(MID(_xlpm.v,10,1)="V",MID(_xlpm.v,10,1)="W",MID(_xlpm.v,10,1)="X")),"X100_AMERICAS_UNIQUE (JLM20301_unique)",AND(LEN(_xlpm.v)=10,LEFT(_xlpm.v,3)="SAJ",OR(_xlpm.mkt="A",_xlpm.mkt="B",_xlpm.mkt="F",_xlpm.mkt="G",_xlpm.mkt="X",_xlpm.mkt="P",_xlpm.mkt="R",_xlpm.mkt="T",_xlpm.mkt="Y",_xlpm.mkt="D",_xlpm.mkt="E",_xlpm.mkt="J",_xlpm.mkt="W"),OR(_xlpm.trans="A",_xlpm.trans="B"),OR(_xlpm.body="41",_xlpm.body="42"),IFERROR(AND(CODE(_xlpm.emis)>=65,CODE(_xlpm.emis)<=88),FALSE),OR(_xlpm.my="X",_xlpm.my="Y",_xlpm.my="1",_xlpm.my="2",_xlpm.my="3",_xlpm.my="4",_xlpm.my="5",_xlpm.my="6",_xlpm.my="7",_xlpm.my="8",_xlpm.my="9")),"XK8-XKR_"&IF(_xlpm.body="41","COUPE_","CONVERTIBLE_")&IF(ISNUMBER(FIND(_xlpm.mkt,"DEJW")),"USA",IF(ISNUMBER(FIND(_xlpm.mkt,"BFGX")),"CANADA","MEXICO"))&IF(_xlpm.trans="A","_AUTO_LHD","_MANUAL_LHD")&"_EMISSION_"&_xlpm.emis&IF(_xlpm.my="X","_1999",IF(_xlpm.my="Y","_2000","_200"&_xlpm.my))&"MY",AND(LEN(_xlpm.v)=10,LEFT(_xlpm.v,3)="SAJ",OR(_xlpm.mkt="A",_xlpm.mkt="B",_xlpm.mkt="D",_xlpm.mkt="E",_xlpm.mkt="F",_xlpm.mkt="J",_xlpm.mkt="K",_xlpm.mkt="P",_xlpm.mkt="R",_xlpm.mkt="W",_xlpm.mkt="X",_xlpm.mkt="Y"),OR(_xlpm.trans="A",_xlpm.trans="C"),OR(_xlpm.body="43",_xlpm.body="4D",_xlpm.body="44",_xlpm.body="4E",_xlpm.body="45",_xlpm.body="46",_xlpm.body="47",_xlpm.body="4F",_xlpm.body="4G"),OR(_xlpm.emis="A",_xlpm.emis="B",_xlpm.emis="C",_xlpm.emis="D",_xlpm.emis="E",_xlpm.emis="F",_xlpm.emis="G",_xlpm.emis="K",_xlpm.emis="N",_xlpm.emis="P",_xlpm.emis="R",_xlpm.emis="S",_xlpm.emis="T",_xlpm.emis="U",_xlpm.emis="V",_xlpm.emis="W",_xlpm.emis="X",_xlpm.emis="Y",_xlpm.emis="1",_xlpm.emis="2",_xlpm.emis="3",_xlpm.emis="4"),OR(_xlpm.my="7",_xlpm.my="8",_xlpm.my="9",_xlpm.my="A",_xlpm.my="B",_xlpm.my="C",_xlpm.my="D",_xlpm.my="E")),"X150_"&IF(_xlpm.my="7","2007MY",IF(_xlpm.my="8","2008MY",IF(_xlpm.my="9","2009MY",IF(_xlpm.my="A","2010MY",IF(_xlpm.my="B","2011MY",IF(_xlpm.my="C","2012MY",IF(_xlpm.my="D","2013MY",IF(_xlpm.my="E","2014MY","UNKNOWN_MY"))))))))&"_MARKET_"&_xlpm.mkt&"_TRANS_"&_xlpm.trans&"_BODY_"&_xlpm.body&"_EMISSION_"&_xlpm.emis&"_CHECK_"&MID(_xlpm.v,9,1),TRUE,IF(LEN(_xlpm.v)<>10,"UNKNOWN: [length="&LEN(_xlpm.v)&"]",IF(LEFT(_xlpm.v,3)<>"SAJ","UNKNOWN: [prefix="&LEFT(_xlpm.v,3)&"]",IF(LEFT(_xlpm.v,5)="SAJJG",IF(NOT(OR(MID(_xlpm.v,7,1)="E",MID(_xlpm.v,7,1)="F")),"UNKNOWN: [7="&MID(_xlpm.v,7,1)&"]",IF(NOT(OR(_xlpm.emis="D",_xlpm.emis="F")),"UNKNOWN: [8="&_xlpm.emis&"]",IF(NOT(OR(MID(_xlpm.v,9,1)="3",MID(_xlpm.v,9,1)="4")),"UNKNOWN: [9="&MID(_xlpm.v,9,1)&"]",IF(NOT(OR(_xlpm.my="A",_xlpm.my="V",_xlpm.my="W",_xlpm.my="X")),"UNKNOWN: [10="&_xlpm.my&"]","UNKNOWN")))),IF(LEFT(_xlpm.v,5)="SAJGX",IF(NOT(OR(MID(_xlpm.v,6,1)="2",MID(_xlpm.v,6,1)="5")),"UNKNOWN: [6="&MID(_xlpm.v,6,1)&"]",IF(NOT(OR(MID(_xlpm.v,7,1)="1",MID(_xlpm.v,7,1)="2",MID(_xlpm.v,7,1)="7")),"UNKNOWN: [7="&MID(_xlpm.v,7,1)&"]",IF(MID(_xlpm.v,8,1)<>"4","UNKNOWN: [8="&MID(_xlpm.v,8,1)&"]",IF(NOT(OR(_xlpm.my="V",_xlpm.my="W",_xlpm.my="X")),"UNKNOWN: [10="&_xlpm.my&"]","UNKNOWN")))),IF(NOT(OR(_xlpm.mkt="A",_xlpm.mkt="B",_xlpm.mkt="F",_xlpm.mkt="G",_xlpm.mkt="X",_xlpm.mkt="P",_xlpm.mkt="R",_xlpm.mkt="T",_xlpm.mkt="Y",_xlpm.mkt="D",_xlpm.mkt="E",_xlpm.mkt="J",_xlpm.mkt="W",_xlpm.mkt="K")),"UNKNOWN: [4="&_xlpm.mkt&"]",IF(NOT(OR(_xlpm.trans="A",_xlpm.trans="B",_xlpm.trans="C")),"UNKNOWN: [5="&_xlpm.trans&"]",IF(NOT(OR(_xlpm.body="41",_xlpm.body="42",_xlpm.body="43",_xlpm.body="4D",_xlpm.body="44",_xlpm.body="45",_xlpm.body="46",_xlpm.body="47",_xlpm.body="4F")),"UNKNOWN: [6-7="&_xlpm.body&"]",IF(NOT(ISNUMBER(SEARCH(_xlpm.emis,"ABCDEFGKNPRSTUVWXY1234"))),"UNKNOWN: [8="&_xlpm.emis&"]",IF(NOT(OR(_xlpm.my="X",_xlpm.my="Y",_xlpm.my="1",_xlpm.my="2",_xlpm.my="3",_xlpm.my="4",_xlpm.my="5",_xlpm.my="6",_xlpm.my="7",_xlpm.my="8",_xlpm.my="9",_xlpm.my="A",_xlpm.my="B",_xlpm.my="C",_xlpm.my="D",_xlpm.my="E")),"UNKNOWN: [10="&_xlpm.my&"]","UNKNOWN")))))))))))} -> X100_AMERICAS_UNIQUE (JLM20301_unique) | D7: {=_xlfn.LET(_xlpm.vin,SUBSTITUTE(CLEAN(TRIM(B7)),CHAR(160),""),_xlpm.rawDate,LEFT(TRIM(E7)&"",8),_xlpm.useDate,IF(RIGHT(_xlpm.rawDate,4)="0000",LEFT(_xlpm.rawDate,4)&"1231",_xlpm.rawDate),_xlpm.bodyCode,MID(_xlpm.vin,6,2),_xlpm.yearCode,MID(_xlpm.vin,10,1),IF(OR(LEN(_xlpm.vin)<>10,LEN(_xlpm.rawDate)<>8),"UNKNOWN",IF(OR(_xlpm.bodyCode="43",_xlpm.bodyCode="4D",_xlpm.bodyCode="44",_xlpm.bodyCode="4E",_xlpm.bodyCode="45",_xlpm.bodyCode="4F",_xlpm.bodyCode="46",_xlpm.bodyCode="4G",_xlpm.bodyCode="47"),_xlfn.SWITCH(_xlpm.yearCode,"6","B00379–B06783","7","B06784–B20074","8","B20075–B27986","9","B27987–B32752","A","B32753–B38853","B","B38854–B44939","C","B44940–B48619","D","B48620–B54164","E","B54165–B56794","F","B56795+","UNKNOWN"),IF(_xlpm.useDate<"19960601","001001–001245",IF(_xlpm.useDate<"19970101","001246–008106",IF(_xlpm.useDate<"19970801","008107–018107",IF(_xlpm.useDate<"19980101","018108–023017",IF(_xlpm.useDate<"19980201","023018–024686",IF(_xlpm.useDate<"19980801","024687–031302",IF(_xlpm.useDate<"19990801","031303–036193",IF(_xlpm.useDate<"20010101","036194–042775",IF(OR(_xlpm.bodyCode="41",_xlpm.bodyCode="42"),_xlfn.SWITCH(_xlpm.yearCode,"Y","A00001–A11050","1","A11051–A22928","2","A22929–A30644","3","A30645–A36873","4","A36874–A42347","5","A42348–A48684","UNKNOWN"),"UNKNOWN"))))))))))))} -> 018108–023017 | E7: ='Ajoneuvorekisteri-Parse Modern '!G73 -> 19970000 | F7: =LEFT(Table34[[#This Row],[Käyttöönotto]],4) -> 1997 | G7: ='Ajoneuvorekisteri-Parse Modern '!AA73 -> 2D CONVERTIBLE XK8 4.0-AUTOMATIC-JGFD/259 Avoauto (AE) 2ov 3990cm3 A | H7: =Ajoneuvorekisteri_Parse_Modern_XK_Range_TieliikenneAvoinData_30_06_2026_csv[[#This Row],[tyyppihyvaksyntanro]] | I7: ='Ajoneuvorekisteri-Parse Modern '!M73 -> 1720 | J7: =IF(AND( OR( ISNUMBER(SEARCH("XK ", G7)), ISNUMBER(SEARCH("XK8", G7)) ), F7 > 2005 ), 1, 0) -> 1 | K7: =IF(OR( ISNUMBER(SEARCH("XKR", G7)), ), 1, 0) -> 0 | L7: =IF(OR( ISNUMBER(SEARCH("COUPE", G7)), ISNUMBER(SEARCH("COUPÉ", G7)), ISNUMBER(SEARCH("COUP�", G7)) ), 1, 0) -> 0 | M7: =IF(OR( ISNUMBER(SEARCH("CONVERTIBLE",G7)), ISNUMBER(SEARCH("AVOAUTO",G7)), ISNUMBER(SEARCH("AVO",G7)), ISNUMBER(SEARCH("CABRIO",G7)) ),1,0) -> 1 | N7: =IF(AND(Table34[[#This Row],[Coupe]]<>1, Table34[[#This Row],[Convertible]]<>1), 1, 0) -> 0 | O7: =IF(L7=1, "Coupe", IF(M7=1, "Convertible", "Unknown")) -> Convertible
A8: ='Ajoneuvorekisteri-Parse Modern '!AO84 -> 2069881 | B8: ='Ajoneuvorekisteri-Parse Modern '!AN84 -> SAJJGXFD4V | C8: {=_xlfn.LET(_xlpm.v,UPPER(SUBSTITUTE(CLEAN(TRIM(B8)),CHAR(160),"")),_xlpm.mkt,MID(_xlpm.v,4,1),_xlpm.trans,MID(_xlpm.v,5,1),_xlpm.body,MID(_xlpm.v,6,2),_xlpm.emis,MID(_xlpm.v,8,1),_xlpm.my,MID(_xlpm.v,10,1),_xlfn.IFS(AND(LEN(_xlpm.v)=10,LEFT(_xlpm.v,5)="SAJJG",OR(MID(_xlpm.v,7,1)="E",MID(_xlpm.v,7,1)="F"),OR(_xlpm.emis="D",_xlpm.emis="F"),OR(MID(_xlpm.v,9,1)="3",MID(_xlpm.v,9,1)="4"),_xlpm.my="A"),"X100_EARLY_NORMAL_AR (JDHT)",AND(LEN(_xlpm.v)=10,LEFT(_xlpm.v,5)="SAJJG",MID(_xlpm.v,6,1)="A",OR(MID(_xlpm.v,7,1)="E",MID(_xlpm.v,7,1)="F"),_xlpm.emis="D",OR(MID(_xlpm.v,9,1)="3",MID(_xlpm.v,9,1)="4"),OR(_xlpm.my="V",_xlpm.my="W",_xlpm.my="X")),"X100_NORMAL (JDHT)",AND(LEN(_xlpm.v)=10,LEFT(_xlpm.v,5)="SAJJG",OR(MID(_xlpm.v,6,1)="A",MID(_xlpm.v,6,1)="K",MID(_xlpm.v,6,1)="N",MID(_xlpm.v,6,1)="X"),OR(MID(_xlpm.v,7,1)="E",MID(_xlpm.v,7,1)="F"),OR(_xlpm.emis="D",_xlpm.emis="F"),OR(MID(_xlpm.v,9,1)="3",MID(_xlpm.v,9,1)="4"),OR(_xlpm.my="V",_xlpm.my="W",_xlpm.my="X")),"X100_JLM20300",AND(LEN(_xlpm.v)=10,LEFT(_xlpm.v,5)="SAJJG",OR(MID(_xlpm.v,6,1)="N",MID(_xlpm.v,6,1)="S",MID(_xlpm.v,6,1)="X"),OR(MID(_xlpm.v,7,1)="E",MID(_xlpm.v,7,1)="F"),OR(_xlpm.emis="D",_xlpm.emis="F"),OR(MID(_xlpm.v,9,1)="3",MID(_xlpm.v,9,1)="4"),OR(MID(_xlpm.v,10,1)="V",MID(_xlpm.v,10,1)="W",MID(_xlpm.v,10,1)="X")),"X100_JLM20301",AND(LEN(_xlpm.v)=10,LEFT(_xlpm.v,5)="SAJGX",OR(MID(_xlpm.v,6,1)="2",MID(_xlpm.v,6,1)="5"),OR(MID(_xlpm.v,7,1)="1",MID(_xlpm.v,7,1)="2",MID(_xlpm.v,7,1)="7"),MID(_xlpm.v,8,1)="4",OR(MID(_xlpm.v,10,1)="V",MID(_xlpm.v,10,1)="W",MID(_xlpm.v,10,1)="X")),"X100_AMERICAS_UNIQUE (JLM20301_unique)",AND(LEN(_xlpm.v)=10,LEFT(_xlpm.v,3)="SAJ",OR(_xlpm.mkt="A",_xlpm.mkt="B",_xlpm.mkt="F",_xlpm.mkt="G",_xlpm.mkt="X",_xlpm.mkt="P",_xlpm.mkt="R",_xlpm.mkt="T",_xlpm.mkt="Y",_xlpm.mkt="D",_xlpm.mkt="E",_xlpm.mkt="J",_xlpm.mkt="W"),OR(_xlpm.trans="A",_xlpm.trans="B"),OR(_xlpm.body="41",_xlpm.body="42"),IFERROR(AND(CODE(_xlpm.emis)>=65,CODE(_xlpm.emis)<=88),FALSE),OR(_xlpm.my="X",_xlpm.my="Y",_xlpm.my="1",_xlpm.my="2",_xlpm.my="3",_xlpm.my="4",_xlpm.my="5",_xlpm.my="6",_xlpm.my="7",_xlpm.my="8",_xlpm.my="9")),"XK8-XKR_"&IF(_xlpm.body="41","COUPE_","CONVERTIBLE_")&IF(ISNUMBER(FIND(_xlpm.mkt,"DEJW")),"USA",IF(ISNUMBER(FIND(_xlpm.mkt,"BFGX")),"CANADA","MEXICO"))&IF(_xlpm.trans="A","_AUTO_LHD","_MANUAL_LHD")&"_EMISSION_"&_xlpm.emis&IF(_xlpm.my="X","_1999",IF(_xlpm.my="Y","_2000","_200"&_xlpm.my))&"MY",AND(LEN(_xlpm.v)=10,LEFT(_xlpm.v,3)="SAJ",OR(_xlpm.mkt="A",_xlpm.mkt="B",_xlpm.mkt="D",_xlpm.mkt="E",_xlpm.mkt="F",_xlpm.mkt="J",_xlpm.mkt="K",_xlpm.mkt="P",_xlpm.mkt="R",_xlpm.mkt="W",_xlpm.mkt="X",_xlpm.mkt="Y"),OR(_xlpm.trans="A",_xlpm.trans="C"),OR(_xlpm.body="43",_xlpm.body="4D",_xlpm.body="44",_xlpm.body="4E",_xlpm.body="45",_xlpm.body="46",_xlpm.body="47",_xlpm.body="4F",_xlpm.body="4G"),OR(_xlpm.emis="A",_xlpm.emis="B",_xlpm.emis="C",_xlpm.emis="D",_xlpm.emis="E",_xlpm.emis="F",_xlpm.emis="G",_xlpm.emis="K",_xlpm.emis="N",_xlpm.emis="P",_xlpm.emis="R",_xlpm.emis="S",_xlpm.emis="T",_xlpm.emis="U",_xlpm.emis="V",_xlpm.emis="W",_xlpm.emis="X",_xlpm.emis="Y",_xlpm.emis="1",_xlpm.emis="2",_xlpm.emis="3",_xlpm.emis="4"),OR(_xlpm.my="7",_xlpm.my="8",_xlpm.my="9",_xlpm.my="A",_xlpm.my="B",_xlpm.my="C",_xlpm.my="D",_xlpm.my="E")),"X150_"&IF(_xlpm.my="7","2007MY",IF(_xlpm.my="8","2008MY",IF(_xlpm.my="9","2009MY",IF(_xlpm.my="A","2010MY",IF(_xlpm.my="B","2011MY",IF(_xlpm.my="C","2012MY",IF(_xlpm.my="D","2013MY",IF(_xlpm.my="E","2014MY","UNKNOWN_MY"))))))))&"_MARKET_"&_xlpm.mkt&"_TRANS_"&_xlpm.trans&"_BODY_"&_xlpm.body&"_EMISSION_"&_xlpm.emis&"_CHECK_"&MID(_xlpm.v,9,1),TRUE,IF(LEN(_xlpm.v)<>10,"UNKNOWN: [length="&LEN(_xlpm.v)&"]",IF(LEFT(_xlpm.v,3)<>"SAJ","UNKNOWN: [prefix="&LEFT(_xlpm.v,3)&"]",IF(LEFT(_xlpm.v,5)="SAJJG",IF(NOT(OR(MID(_xlpm.v,7,1)="E",MID(_xlpm.v,7,1)="F")),"UNKNOWN: [7="&MID(_xlpm.v,7,1)&"]",IF(NOT(OR(_xlpm.emis="D",_xlpm.emis="F")),"UNKNOWN: [8="&_xlpm.emis&"]",IF(NOT(OR(MID(_xlpm.v,9,1)="3",MID(_xlpm.v,9,1)="4")),"UNKNOWN: [9="&MID(_xlpm.v,9,1)&"]",IF(NOT(OR(_xlpm.my="A",_xlpm.my="V",_xlpm.my="W",_xlpm.my="X")),"UNKNOWN: [10="&_xlpm.my&"]","UNKNOWN")))),IF(LEFT(_xlpm.v,5)="SAJGX",IF(NOT(OR(MID(_xlpm.v,6,1)="2",MID(_xlpm.v,6,1)="5")),"UNKNOWN: [6="&MID(_xlpm.v,6,1)&"]",IF(NOT(OR(MID(_xlpm.v,7,1)="1",MID(_xlpm.v,7,1)="2",MID(_xlpm.v,7,1)="7")),"UNKNOWN: [7="&MID(_xlpm.v,7,1)&"]",IF(MID(_xlpm.v,8,1)<>"4","UNKNOWN: [8="&MID(_xlpm.v,8,1)&"]",IF(NOT(OR(_xlpm.my="V",_xlpm.my="W",_xlpm.my="X")),"UNKNOWN: [10="&_xlpm.my&"]","UNKNOWN")))),IF(NOT(OR(_xlpm.mkt="A",_xlpm.mkt="B",_xlpm.mkt="F",_xlpm.mkt="G",_xlpm.mkt="X",_xlpm.mkt="P",_xlpm.mkt="R",_xlpm.mkt="T",_xlpm.mkt="Y",_xlpm.mkt="D",_xlpm.mkt="E",_xlpm.mkt="J",_xlpm.mkt="W",_xlpm.mkt="K")),"UNKNOWN: [4="&_xlpm.mkt&"]",IF(NOT(OR(_xlpm.trans="A",_xlpm.trans="B",_xlpm.trans="C")),"UNKNOWN: [5="&_xlpm.trans&"]",IF(NOT(OR(_xlpm.body="41",_xlpm.body="42",_xlpm.body="43",_xlpm.body="4D",_xlpm.body="44",_xlpm.body="45",_xlpm.body="46",_xlpm.body="47",_xlpm.body="4F")),"UNKNOWN: [6-7="&_xlpm.body&"]",IF(NOT(ISNUMBER(SEARCH(_xlpm.emis,"ABCDEFGKNPRSTUVWXY1234"))),"UNKNOWN: [8="&_xlpm.emis&"]",IF(NOT(OR(_xlpm.my="X",_xlpm.my="Y",_xlpm.my="1",_xlpm.my="2",_xlpm.my="3",_xlpm.my="4",_xlpm.my="5",_xlpm.my="6",_xlpm.my="7",_xlpm.my="8",_xlpm.my="9",_xlpm.my="A",_xlpm.my="B",_xlpm.my="C",_xlpm.my="D",_xlpm.my="E")),"UNKNOWN: [10="&_xlpm.my&"]","UNKNOWN")))))))))))} -> X100_JLM20300 | D8: {=_xlfn.LET(_xlpm.vin,SUBSTITUTE(CLEAN(TRIM(B8)),CHAR(160),""),_xlpm.rawDate,LEFT(TRIM(E8)&"",8),_xlpm.useDate,IF(RIGHT(_xlpm.rawDate,4)="0000",LEFT(_xlpm.rawDate,4)&"1231",_xlpm.rawDate),_xlpm.bodyCode,MID(_xlpm.vin,6,2),_xlpm.yearCode,MID(_xlpm.vin,10,1),IF(OR(LEN(_xlpm.vin)<>10,LEN(_xlpm.rawDate)<>8),"UNKNOWN",IF(OR(_xlpm.bodyCode="43",_xlpm.bodyCode="4D",_xlpm.bodyCode="44",_xlpm.bodyCode="4E",_xlpm.bodyCode="45",_xlpm.bodyCode="4F",_xlpm.bodyCode="46",_xlpm.bodyCode="4G",_xlpm.bodyCode="47"),_xlfn.SWITCH(_xlpm.yearCode,"6","B00379–B06783","7","B06784–B20074","8","B20075–B27986","9","B27987–B32752","A","B32753–B38853","B","B38854–B44939","C","B44940–B48619","D","B48620–B54164","E","B54165–B56794","F","B56795+","UNKNOWN"),IF(_xlpm.useDate<"19960601","001001–001245",IF(_xlpm.useDate<"19970101","001246–008106",IF(_xlpm.useDate<"19970801","008107–018107",IF(_xlpm.useDate<"19980101","018108–023017",IF(_xlpm.useDate<"19980201","023018–024686",IF(_xlpm.useDate<"19980801","024687–031302",IF(_xlpm.useDate<"19990801","031303–036193",IF(_xlpm.useDate<"20010101","036194–042775",IF(OR(_xlpm.bodyCode="41",_xlpm.bodyCode="42"),_xlfn.SWITCH(_xlpm.yearCode,"Y","A00001–A11050","1","A11051–A22928","2","A22929–A30644","3","A30645–A36873","4","A36874–A42347","5","A42348–A48684","UNKNOWN"),"UNKNOWN"))))))))))))} -> 018108–023017 | E8: ='Ajoneuvorekisteri-Parse Modern '!G84 -> 19970000 | F8: =LEFT(Table34[[#This Row],[Käyttöönotto]],4) -> 1997 | G8: ='Ajoneuvorekisteri-Parse Modern '!AA84 -> XK8 Avoauto (AE) 2ov 3990cm3 A | H8: =Ajoneuvorekisteri_Parse_Modern_XK_Range_TieliikenneAvoinData_30_06_2026_csv[[#This Row],[tyyppihyvaksyntanro]] -> e11*95/54*0061*04 | I8: ='Ajoneuvorekisteri-Parse Modern '!M84 -> 1825 | J8: =IF(AND( OR( ISNUMBER(SEARCH("XK ", G8)), ISNUMBER(SEARCH("XK8", G8)) ), F8 > 2005 ), 1, 0) -> 1 | K8: =IF(OR( ISNUMBER(SEARCH("XKR", G8)), ), 1, 0) -> 0 | L8: =IF(OR( ISNUMBER(SEARCH("COUPE", G8)), ISNUMBER(SEARCH("COUPÉ", G8)), ISNUMBER(SEARCH("COUP�", G8)) ), 1, 0) -> 0 | M8: =IF(OR( ISNUMBER(SEARCH("CONVERTIBLE",G8)), ISNUMBER(SEARCH("AVOAUTO",G8)), ISNUMBER(SEARCH("AVO",G8)), ISNUMBER(SEARCH("CABRIO",G8)) ),1,0) -> 1 | N8: =IF(AND(Table34[[#This Row],[Coupe]]<>1, Table34[[#This Row],[Convertible]]<>1), 1, 0) -> 0 | O8: =IF(L8=1, "Coupe", IF(M8=1, "Convertible", "Unknown")) -> Convertible
